Workbook

Sheet MVd H121
A1: P | B1: 341 | C1: kN | D1: V/P | E1: =C9/B1 -> 0.66666667
A2: L | B2: 9 | C2: m
A3: a | B3: 3 | C3: m
A4: d | B4: 1.145 | C4: m
A5: R_1 | B5: =(B2-B3)/B2*B1 -> 227.33333 | C5: kN
A6: R_2 | B6: =B3/B2*B1 -> 113.66667 | C6: kN
A8: x | B8: M | C8: V | D8: M/(Vd)
A9: 0 | B9: =IF(A9<=B$3, A9*B$5, (B$2-A9)*B$6) -> 0 | C9: =IF(A9<=B$3, B$5, -B$6) -> 227.33333 | D9: =B9/(C9*B$4) -> 0
A10: 0.5 | B10: =IF(A10<=B$3, A10*B$5, (B$2-A10)*B$6) -> 113.66667 | C10: =IF(A10<=B$3, B$5, -B$6) -> 227.33333 | D10: =B10/(C10*B$4) -> 0.43668122 | E10: =A10/D10 -> 1.145
A11: 1 | B11: =IF(A11<=B$3, A11*B$5, (B$2-A11)*B$6) -> 227.33333 | C11: =IF(A11<=B$3, B$5, -B$6) -> 227.33333 | D11: =B11/(C11*B$4) -> 0.87336245 | E11: =A11/D11 -> 1.145
A12: 1.5 | B12: =IF(A12<=B$3, A12*B$5, (B$2-A12)*B$6) -> 341 | C12: =IF(A12<=B$3, B$5, -B$6) -> 227.33333 | D12: =B12/(C12*B$4) -> 1.3100437 | E12: =A12/D12 -> 1.145
A13: 2 | B13: =IF(A13<=B$3, A13*B$5, (B$2-A13)*B$6) -> 454.66667 | C13: =IF(A13<=B$3, B$5, -B$6) -> 227.33333 | D13: =B13/(C13*B$4) -> 1.7467249 | E13: =A13/D13 -> 1.145
A14: 2.5 | B14: =IF(A14<=B$3, A14*B$5, (B$2-A14)*B$6) -> 568.33333 | C14: =IF(A14<=B$3, B$5, -B$6) -> 227.33333 | D14: =B14/(C14*B$4) -> 2.1834061 | E14: =A14/D14 -> 1.145
A15: 3 | B15: =IF(A15<=B$3, A15*B$5, (B$2-A15)*B$6) -> 682 | C15: =IF(A15<=B$3, B$5, -B$6) -> 227.33333 | D15: =B15/(C15*B$4) -> 2.6200873 | E15: =A15/D15 -> 1.145
A16: 3.000001 | B16: =IF(A16<=B$3, A16*B$5, (B$2-A16)*B$6) -> 681.99989 | C16: =IF(A16<=B$3, B$5, -B$6) -> -113.66667 | D16: =B16/(C16*B$4) -> -5.2401738 | E16: =A16/D16 -> -0.57250029
A17: 3.5 | B17: =IF(A17<=B$3, A17*B$5, (B$2-A17)*B$6) -> 625.16667 | C17: =IF(A17<=B$3, B$5, -B$6) -> -113.66667 | D17: =B17/(C17*B$4) -> -4.8034934 | E17: =A17/D17 -> -0.72863636
A18: 4 | B18: =IF(A18<=B$3, A18*B$5, (B$2-A18)*B$6) -> 568.33333 | C18: =IF(A18<=B$3, B$5, -B$6) -> -113.66667 | D18: =B18/(C18*B$4) -> -4.3668122 | E18: =A18/D18 -> -0.916
A19: 4.000001 | B19: =IF(A19<=B$3, A19*B$5, (B$2-A19)*B$6) -> 568.33322 | C19: =IF(A19<=B$3, B$5, -B$6) -> -113.66667 | D19: =B19/(C19*B$4) -> -4.3668114 | E19: =A19/D19 -> -0.91600041
A20: 4.5 | B20: =IF(A20<=B$3, A20*B$5, (B$2-A20)*B$6) -> 511.5 | C20: =IF(A20<=B$3, B$5, -B$6) -> -113.66667 | D20: =B20/(C20*B$4) -> -3.930131 | E20: =A20/D20 -> -1.145
A21: 4.500001 | B21: =IF(A21<=B$3, A21*B$5, (B$2-A21)*B$6) -> 511.49989 | C21: =IF(A21<=B$3, B$5, -B$6) -> -113.66667 | D21: =B21/(C21*B$4) -> -3.9301301 | E21: =A21/D21 -> -1.1450005
... A25: 6.5 | B25: =IF(A25<=B$3, A25*B$5, (B$2-A25)*B$6) -> 284.16667 | C25: =IF(A25<=B$3, B$5, -B$6) -> -113.66667 | D25: =B25/(C25*B$4) -> -2.1834061 | E25: =A25/D25 -> -2.977
A26: 7 | B26: =IF(A26<=B$3, A26*B$5, (B$2-A26)*B$6) -> 227.33333 | C26: =IF(A26<=B$3, B$5, -B$6) -> -113.66667 | D26: =B26/(C26*B$4) -> -1.7467249 | E26: =A26/D26 -> -4.0075 | P26: b | Q26: 0.3 | R26: m
A27: 7.5 | B27: =IF(A27<=B$3, A27*B$5, (B$2-A27)*B$6) -> 170.5 | C27: =IF(A27<=B$3, B$5, -B$6) -> -113.66667 | D27: =B27/(C27*B$4) -> -1.3100437 | E27: =A27/D27 -> -5.725 | P27: h | Q27: 1.2 | R27: m
A28: 8 | B28: =IF(A28<=B$3, A28*B$5, (B$2-A28)*B$6) -> 113.66667 | C28: =IF(A28<=B$3, B$5, -B$6) -> -113.66667 | D28: =B28/(C28*B$4) -> -0.87336245 | E28: =A28/D28 -> -9.16 | P28: rho | Q28: 2450 | R28: kg/m3
A29: 8.5 | B29: =IF(A29<=B$3, A29*B$5, (B$2-A29)*B$6) -> 56.833333 | C29: =IF(A29<=B$3, B$5, -B$6) -> -113.66667 | D29: =B29/(C29*B$4) -> -0.43668122 | E29: =A29/D29 -> -19.465 | P29: g | Q29: 9.81 | R29: m/s^2
A30: 9 | B30: =IF(A30<=B$3, A30*B$5, (B$2-A30)*B$6) -> 0 | C30: =IF(A30<=B$3, B$5, -B$6) -> -113.66667 | D30: =B30/(C30*B$4) -> 0 | P30: G | Q30: =Q26*Q27*Q28*Q29/1000 -> 8.65242 | R30: kN/m
P31: V_G_sup | Q31: =Q30*B2/2 -> 38.93589 | R31: kN
P32: V (1 m) | Q32: =(4.5-1)/4.5*Q31 -> 30.28347 | R32: kN
P33: V (2 m) | Q33: =(4.5-2)/4.5*Q31 -> 21.63105 | R33: kN | S33: hier ongeveer de inclined shear crack

Sheet MVd H401
A1: P | B1: 263 | C1: kN | D1: V/P | E1: =C9/B1 -> 0.5
A2: L | B2: 9 | C2: m
A3: a | B3: 4.5 | C3: m
A4: d | B4: 1.158 | C4: m
A5: R_1 | B5: =(B2-B3)/B2*B1 -> 131.5 | C5: kN
A6: R_2 | B6: =B3/B2*B1 -> 131.5 | C6: kN
A8: x | B8: M | C8: V | D8: M/(Vd)
A9: 0 | B9: =IF(A9<=B$3, A9*B$5, (B$2-A9)*B$6) -> 0 | C9: =IF(A9<=B$3, B$5, -B$6) -> 131.5 | D9: =B9/(C9*B$4) -> 0
A10: 0.5 | B10: =IF(A10<=B$3, A10*B$5, (B$2-A10)*B$6) -> 65.75 | C10: =IF(A10<=B$3, B$5, -B$6) -> 131.5 | D10: =B10/(C10*B$4) -> 0.43177893 | E10: =A10/D10 -> 1.158
A11: 1 | B11: =IF(A11<=B$3, A11*B$5, (B$2-A11)*B$6) -> 131.5 | C11: =IF(A11<=B$3, B$5, -B$6) -> 131.5 | D11: =B11/(C11*B$4) -> 0.86355786 | E11: =A11/D11 -> 1.158
A12: 1.5 | B12: =IF(A12<=B$3, A12*B$5, (B$2-A12)*B$6) -> 197.25 | C12: =IF(A12<=B$3, B$5, -B$6) -> 131.5 | D12: =B12/(C12*B$4) -> 1.2953368 | E12: =A12/D12 -> 1.158
A13: 2 | B13: =IF(A13<=B$3, A13*B$5, (B$2-A13)*B$6) -> 263 | C13: =IF(A13<=B$3, B$5, -B$6) -> 131.5 | D13: =B13/(C13*B$4) -> 1.7271157 | E13: =A13/D13 -> 1.158
A14: 2.5 | B14: =IF(A14<=B$3, A14*B$5, (B$2-A14)*B$6) -> 328.75 | C14: =IF(A14<=B$3, B$5, -B$6) -> 131.5 | D14: =B14/(C14*B$4) -> 2.1588946 | E14: =A14/D14 -> 1.158
A15: 3 | B15: =IF(A15<=B$3, A15*B$5, (B$2-A15)*B$6) -> 394.5 | C15: =IF(A15<=B$3, B$5, -B$6) -> 131.5 | D15: =B15/(C15*B$4) -> 2.5906736 | E15: =A15/D15 -> 1.158
A16: 3.000001 | B16: =IF(A16<=B$3, A16*B$5, (B$2-A16)*B$6) -> 394.50013 | C16: =IF(A16<=B$3, B$5, -B$6) -> 131.5 | D16: =B16/(C16*B$4) -> 2.5906744 | E16: =A16/D16 -> 1.158
A17: 3.5 | B17: =IF(A17<=B$3, A17*B$5, (B$2-A17)*B$6) -> 460.25 | C17: =IF(A17<=B$3, B$5, -B$6) -> 131.5 | D17: =B17/(C17*B$4) -> 3.0224525 | E17: =A17/D17 -> 1.158
A18: 4 | B18: =IF(A18<=B$3, A18*B$5, (B$2-A18)*B$6) -> 526 | C18: =IF(A18<=B$3, B$5, -B$6) -> 131.5 | D18: =B18/(C18*B$4) -> 3.4542314 | E18: =A18/D18 -> 1.158
A19: 4.000001 | B19: =IF(A19<=B$3, A19*B$5, (B$2-A19)*B$6) -> 526.00013 | C19: =IF(A19<=B$3, B$5, -B$6) -> 131.5 | D19: =B19/(C19*B$4) -> 3.4542323 | E19: =A19/D19 -> 1.158
A20: 4.5 | B20: =IF(A20<=B$3, A20*B$5, (B$2-A20)*B$6) -> 591.75 | C20: =IF(A20<=B$3, B$5, -B$6) -> 131.5 | D20: =B20/(C20*B$4) -> 3.8860104 | E20: =A20/D20 -> 1.158
A21: 4.500001 | B21: =IF(A21<=B$3, A21*B$5, (B$2-A21)*B$6) -> 591.74987 | C21: =IF(A21<=B$3, B$5, -B$6) -> -131.5 | D21: =B21/(C21*B$4) -> -3.8860095 | E21: =A21/D21 -> -1.1580005
... A25: 6.5 | B25: =IF(A25<=B$3, A25*B$5, (B$2-A25)*B$6) -> 328.75 | C25: =IF(A25<=B$3, B$5, -B$6) -> -131.5 | D25: =B25/(C25*B$4) -> -2.1588946 | E25: =A25/D25 -> -3.0108
A26: 7 | B26: =IF(A26<=B$3, A26*B$5, (B$2-A26)*B$6) -> 263 | C26: =IF(A26<=B$3, B$5, -B$6) -> -131.5 | D26: =B26/(C26*B$4) -> -1.7271157 | E26: =A26/D26 -> -4.053 | P26: b | Q26: 0.3 | R26: m
A27: 7.5 | B27: =IF(A27<=B$3, A27*B$5, (B$2-A27)*B$6) -> 197.25 | C27: =IF(A27<=B$3, B$5, -B$6) -> -131.5 | D27: =B27/(C27*B$4) -> -1.2953368 | E27: =A27/D27 -> -5.79 | P27: h | Q27: 1.2 | R27: m
A28: 8 | B28: =IF(A28<=B$3, A28*B$5, (B$2-A28)*B$6) -> 131.5 | C28: =IF(A28<=B$3, B$5, -B$6) -> -131.5 | D28: =B28/(C28*B$4) -> -0.86355786 | E28: =A28/D28 -> -9.264 | P28: rho | Q28: 2450 | R28: kg/m3
A29: 8.5 | B29: =IF(A29<=B$3, A29*B$5, (B$2-A29)*B$6) -> 65.75 | C29: =IF(A29<=B$3, B$5, -B$6) -> -131.5 | D29: =B29/(C29*B$4) -> -0.43177893 | E29: =A29/D29 -> -19.686 | P29: g | Q29: 9.81 | R29: m/s^2
A30: 9 | B30: =IF(A30<=B$3, A30*B$5, (B$2-A30)*B$6) -> 0 | C30: =IF(A30<=B$3, B$5, -B$6) -> -131.5 | D30: =B30/(C30*B$4) -> 0 | P30: G | Q30: =Q26*Q27*Q28*Q29/1000 -> 8.65242 | R30: kN/m
P31: V_G_sup | Q31: =Q30*B2/2 -> 38.93589 | R31: kN
P32: V (1 m) | Q32: =(4.5-1)/4.5*Q31 -> 30.28347 | R32: kN
P33: V (2 m) | Q33: =(4.5-2)/4.5*Q31 -> 21.63105 | R33: kN | S33: hier ongeveer de inclined shear crack

Sheet MVd H403
A1: P | B1: 346 | C1: kN | D1: V/P | E1: =C9/B1 -> 0.5
A2: L | B2: 9 | C2: m
A3: a | B3: 4.5 | C3: m
A4: d | B4: 1.158 | C4: m
A5: R_1 | B5: =(B2-B3)/B2*B1 -> 173 | C5: kN
A6: R_2 | B6: =B3/B2*B1 -> 173 | C6: kN
A8: x | B8: M | C8: V | D8: M/(Vd)
A9: 0 | B9: =IF(A9<=B$3, A9*B$5, (B$2-A9)*B$6) -> 0 | C9: =IF(A9<=B$3, B$5, -B$6) -> 173 | D9: =B9/(C9*B$4) -> 0
A10: 0.5 | B10: =IF(A10<=B$3, A10*B$5, (B$2-A10)*B$6) -> 86.5 | C10: =IF(A10<=B$3, B$5, -B$6) -> 173 | D10: =B10/(C10*B$4) -> 0.43177893 | E10: =A10/D10 -> 1.158
A11: 1 | B11: =IF(A11<=B$3, A11*B$5, (B$2-A11)*B$6) -> 173 | C11: =IF(A11<=B$3, B$5, -B$6) -> 173 | D11: =B11/(C11*B$4) -> 0.86355786 | E11: =A11/D11 -> 1.158
A12: 1.5 | B12: =IF(A12<=B$3, A12*B$5, (B$2-A12)*B$6) -> 259.5 | C12: =IF(A12<=B$3, B$5, -B$6) -> 173 | D12: =B12/(C12*B$4) -> 1.2953368 | E12: =A12/D12 -> 1.158
A13: 2 | B13: =IF(A13<=B$3, A13*B$5, (B$2-A13)*B$6) -> 346 | C13: =IF(A13<=B$3, B$5, -B$6) -> 173 | D13: =B13/(C13*B$4) -> 1.7271157 | E13: =A13/D13 -> 1.158
A14: 2.5 | B14: =IF(A14<=B$3, A14*B$5, (B$2-A14)*B$6) -> 432.5 | C14: =IF(A14<=B$3, B$5, -B$6) -> 173 | D14: =B14/(C14*B$4) -> 2.1588946 | E14: =A14/D14 -> 1.158
A15: 3 | B15: =IF(A15<=B$3, A15*B$5, (B$2-A15)*B$6) -> 519 | C15: =IF(A15<=B$3, B$5, -B$6) -> 173 | D15: =B15/(C15*B$4) -> 2.5906736 | E15: =A15/D15 -> 1.158
A16: 3.000001 | B16: =IF(A16<=B$3, A16*B$5, (B$2-A16)*B$6) -> 519.00017 | C16: =IF(A16<=B$3, B$5, -B$6) -> 173 | D16: =B16/(C16*B$4) -> 2.5906744 | E16: =A16/D16 -> 1.158
A17: 3.5 | B17: =IF(A17<=B$3, A17*B$5, (B$2-A17)*B$6) -> 605.5 | C17: =IF(A17<=B$3, B$5, -B$6) -> 173 | D17: =B17/(C17*B$4) -> 3.0224525 | E17: =A17/D17 -> 1.158
A18: 4 | B18: =IF(A18<=B$3, A18*B$5, (B$2-A18)*B$6) -> 692 | C18: =IF(A18<=B$3, B$5, -B$6) -> 173 | D18: =B18/(C18*B$4) -> 3.4542314 | E18: =A18/D18 -> 1.158
A19: 4.000001 | B19: =IF(A19<=B$3, A19*B$5, (B$2-A19)*B$6) -> 692.00017 | C19: =IF(A19<=B$3, B$5, -B$6) -> 173 | D19: =B19/(C19*B$4) -> 3.4542323 | E19: =A19/D19 -> 1.158
A20: 4.5 | B20: =IF(A20<=B$3, A20*B$5, (B$2-A20)*B$6) -> 778.5 | C20: =IF(A20<=B$3, B$5, -B$6) -> 173 | D20: =B20/(C20*B$4) -> 3.8860104 | E20: =A20/D20 -> 1.158
A21: 4.500001 | B21: =IF(A21<=B$3, A21*B$5, (B$2-A21)*B$6) -> 778.49983 | C21: =IF(A21<=B$3, B$5, -B$6) -> -173 | D21: =B21/(C21*B$4) -> -3.8860095 | E21: =A21/D21 -> -1.1580005
... A25: 6.5 | B25: =IF(A25<=B$3, A25*B$5, (B$2-A25)*B$6) -> 432.5 | C25: =IF(A25<=B$3, B$5, -B$6) -> -173 | D25: =B25/(C25*B$4) -> -2.1588946 | E25: =A25/D25 -> -3.0108
A26: 7 | B26: =IF(A26<=B$3, A26*B$5, (B$2-A26)*B$6) -> 346 | C26: =IF(A26<=B$3, B$5, -B$6) -> -173 | D26: =B26/(C26*B$4) -> -1.7271157 | E26: =A26/D26 -> -4.053 | P26: b | Q26: 0.3 | R26: m
A27: 7.5 | B27: =IF(A27<=B$3, A27*B$5, (B$2-A27)*B$6) -> 259.5 | C27: =IF(A27<=B$3, B$5, -B$6) -> -173 | D27: =B27/(C27*B$4) -> -1.2953368 | E27: =A27/D27 -> -5.79 | P27: h | Q27: 1.2 | R27: m
A28: 8 | B28: =IF(A28<=B$3, A28*B$5, (B$2-A28)*B$6) -> 173 | C28: =IF(A28<=B$3, B$5, -B$6) -> -173 | D28: =B28/(C28*B$4) -> -0.86355786 | E28: =A28/D28 -> -9.264 | P28: rho | Q28: 2450 | R28: kg/m3
A29: 8.5 | B29: =IF(A29<=B$3, A29*B$5, (B$2-A29)*B$6) -> 86.5 | C29: =IF(A29<=B$3, B$5, -B$6) -> -173 | D29: =B29/(C29*B$4) -> -0.43177893 | E29: =A29/D29 -> -19.686 | P29: g | Q29: 9.81 | R29: m/s^2
A30: 9 | B30: =IF(A30<=B$3, A30*B$5, (B$2-A30)*B$6) -> 0 | C30: =IF(A30<=B$3, B$5, -B$6) -> -173 | D30: =B30/(C30*B$4) -> 0 | P30: G | Q30: =Q26*Q27*Q28*Q29/1000 -> 8.65242 | R30: kN/m
P31: V_G_sup | Q31: =Q30*B2/2 -> 38.93589 | R31: kN
P32: V (1 m) | Q32: =(4.5-1)/4.5*Q31 -> 30.28347 | R32: kN
P33: V (2 m) | Q33: =(4.5-2)/4.5*Q31 -> 21.63105 | R33: kN | S33: hier ongeveer de inclined shear crack

Sheet MVd H404
A1: P | B1: 269 | C1: kN | D1: V/P | E1: =C9/B1 -> 0.55555556
A2: L | B2: 9 | C2: m
A3: a | B3: 4 | C3: m
A4: d | B4: 1.158 | C4: m
A5: R_1 | B5: =(B2-B3)/B2*B1 -> 149.44444 | C5: kN
A6: R_2 | B6: =B3/B2*B1 -> 119.55556 | C6: kN
A8: x | B8: M | C8: V | D8: M/(Vd)
A9: 0 | B9: =IF(A9<=B$3, A9*B$5, (B$2-A9)*B$6) -> 0 | C9: =IF(A9<=B$3, B$5, -B$6) -> 149.44444 | D9: =B9/(C9*B$4) -> 0
A10: 0.5 | B10: =IF(A10<=B$3, A10*B$5, (B$2-A10)*B$6) -> 74.722222 | C10: =IF(A10<=B$3, B$5, -B$6) -> 149.44444 | D10: =B10/(C10*B$4) -> 0.43177893 | E10: =A10/D10 -> 1.158
A11: 1 | B11: =IF(A11<=B$3, A11*B$5, (B$2-A11)*B$6) -> 149.44444 | C11: =IF(A11<=B$3, B$5, -B$6) -> 149.44444 | D11: =B11/(C11*B$4) -> 0.86355786 | E11: =A11/D11 -> 1.158
A12: 1.5 | B12: =IF(A12<=B$3, A12*B$5, (B$2-A12)*B$6) -> 224.16667 | C12: =IF(A12<=B$3, B$5, -B$6) -> 149.44444 | D12: =B12/(C12*B$4) -> 1.2953368 | E12: =A12/D12 -> 1.158
A13: 2 | B13: =IF(A13<=B$3, A13*B$5, (B$2-A13)*B$6) -> 298.88889 | C13: =IF(A13<=B$3, B$5, -B$6) -> 149.44444 | D13: =B13/(C13*B$4) -> 1.7271157 | E13: =A13/D13 -> 1.158
A14: 2.5 | B14: =IF(A14<=B$3, A14*B$5, (B$2-A14)*B$6) -> 373.61111 | C14: =IF(A14<=B$3, B$5, -B$6) -> 149.44444 | D14: =B14/(C14*B$4) -> 2.1588946 | E14: =A14/D14 -> 1.158
A15: 3 | B15: =IF(A15<=B$3, A15*B$5, (B$2-A15)*B$6) -> 448.33333 | C15: =IF(A15<=B$3, B$5, -B$6) -> 149.44444 | D15: =B15/(C15*B$4) -> 2.5906736 | E15: =A15/D15 -> 1.158
A16: 3.000001 | B16: =IF(A16<=B$3, A16*B$5, (B$2-A16)*B$6) -> 448.33348 | C16: =IF(A16<=B$3, B$5, -B$6) -> 149.44444 | D16: =B16/(C16*B$4) -> 2.5906744 | E16: =A16/D16 -> 1.158
A17: 3.5 | B17: =IF(A17<=B$3, A17*B$5, (B$2-A17)*B$6) -> 523.05556 | C17: =IF(A17<=B$3, B$5, -B$6) -> 149.44444 | D17: =B17/(C17*B$4) -> 3.0224525 | E17: =A17/D17 -> 1.158
A18: 4 | B18: =IF(A18<=B$3, A18*B$5, (B$2-A18)*B$6) -> 597.77778 | C18: =IF(A18<=B$3, B$5, -B$6) -> 149.44444 | D18: =B18/(C18*B$4) -> 3.4542314 | E18: =A18/D18 -> 1.158
A19: 4.000001 | B19: =IF(A19<=B$3, A19*B$5, (B$2-A19)*B$6) -> 597.77766 | C19: =IF(A19<=B$3, B$5, -B$6) -> -119.55556 | D19: =B19/(C19*B$4) -> -4.3177884 | E19: =A19/D19 -> -0.92640042
A20: 4.5 | B20: =IF(A20<=B$3, A20*B$5, (B$2-A20)*B$6) -> 538 | C20: =IF(A20<=B$3, B$5, -B$6) -> -119.55556 | D20: =B20/(C20*B$4) -> -3.8860104 | E20: =A20/D20 -> -1.158
A21: 4.500001 | B21: =IF(A21<=B$3, A21*B$5, (B$2-A21)*B$6) -> 537.99988 | C21: =IF(A21<=B$3, B$5, -B$6) -> -119.55556 | D21: =B21/(C21*B$4) -> -3.8860095 | E21: =A21/D21 -> -1.1580005
... A25: 6.5 | B25: =IF(A25<=B$3, A25*B$5, (B$2-A25)*B$6) -> 298.88889 | C25: =IF(A25<=B$3, B$5, -B$6) -> -119.55556 | D25: =B25/(C25*B$4) -> -2.1588946 | E25: =A25/D25 -> -3.0108
A26: 7 | B26: =IF(A26<=B$3, A26*B$5, (B$2-A26)*B$6) -> 239.11111 | C26: =IF(A26<=B$3, B$5, -B$6) -> -119.55556 | D26: =B26/(C26*B$4) -> -1.7271157 | E26: =A26/D26 -> -4.053 | P26: b | Q26: 0.3 | R26: m
A27: 7.5 | B27: =IF(A27<=B$3, A27*B$5, (B$2-A27)*B$6) -> 179.33333 | C27: =IF(A27<=B$3, B$5, -B$6) -> -119.55556 | D27: =B27/(C27*B$4) -> -1.2953368 | E27: =A27/D27 -> -5.79 | P27: h | Q27: 1.2 | R27: m
A28: 8 | B28: =IF(A28<=B$3, A28*B$5, (B$2-A28)*B$6) -> 119.55556 | C28: =IF(A28<=B$3, B$5, -B$6) -> -119.55556 | D28: =B28/(C28*B$4) -> -0.86355786 | E28: =A28/D28 -> -9.264 | P28: rho | Q28: 2450 | R28: kg/m3
A29: 8.5 | B29: =IF(A29<=B$3, A29*B$5, (B$2-A29)*B$6) -> 59.777778 | C29: =IF(A29<=B$3, B$5, -B$6) -> -119.55556 | D29: =B29/(C29*B$4) -> -0.43177893 | E29: =A29/D29 -> -19.686 | P29: g | Q29: 9.81 | R29: m/s^2
A30: 9 | B30: =IF(A30<=B$3, A30*B$5, (B$2-A30)*B$6) -> 0 | C30: =IF(A30<=B$3, B$5, -B$6) -> -119.55556 | D30: =B30/(C30*B$4) -> 0 | P30: G | Q30: =Q26*Q27*Q28*Q29/1000 -> 8.65242 | R30: kN/m
P31: V_G_sup | Q31: =Q30*B2/2 -> 38.93589 | R31: kN
P32: V (1 m) | Q32: =(4.5-1)/4.5*Q31 -> 30.28347 | R32: kN
P33: V (2 m) | Q33: =(4.5-2)/4.5*Q31 -> 21.63105 | R33: kN | S33: hier ongeveer de inclined shear crack

Sheet MVd H602
A1: P | B1: 306 | C1: kN | D1: V/P | E1: =C9/B1 -> 0.5
A2: L | B2: 9 | C2: m
A3: a | B3: 4.5 | C3: m
A4: d | B4: 1.158 | C4: m
A5: R_1 | B5: =(B2-B3)/B2*B1 -> 153 | C5: kN
A6: R_2 | B6: =B3/B2*B1 -> 153 | C6: kN
A8: x | B8: M | C8: V | D8: M/(Vd)
A9: 0 | B9: =IF(A9<=B$3, A9*B$5, (B$2-A9)*B$6) -> 0 | C9: =IF(A9<=B$3, B$5, -B$6) -> 153 | D9: =B9/(C9*B$4) -> 0
A10: 0.5 | B10: =IF(A10<=B$3, A10*B$5, (B$2-A10)*B$6) -> 76.5 | C10: =IF(A10<=B$3, B$5, -B$6) -> 153 | D10: =B10/(C10*B$4) -> 0.43177893 | E10: =A10/D10 -> 1.158
A11: 1 | B11: =IF(A11<=B$3, A11*B$5, (B$2-A11)*B$6) -> 153 | C11: =IF(A11<=B$3, B$5, -B$6) -> 153 | D11: =B11/(C11*B$4) -> 0.86355786 | E11: =A11/D11 -> 1.158
A12: 1.5 | B12: =IF(A12<=B$3, A12*B$5, (B$2-A12)*B$6) -> 229.5 | C12: =IF(A12<=B$3, B$5, -B$6) -> 153 | D12: =B12/(C12*B$4) -> 1.2953368 | E12: =A12/D12 -> 1.158
A13: 2 | B13: =IF(A13<=B$3, A13*B$5, (B$2-A13)*B$6) -> 306 | C13: =IF(A13<=B$3, B$5, -B$6) -> 153 | D13: =B13/(C13*B$4) -> 1.7271157 | E13: =A13/D13 -> 1.158
A14: 2.5 | B14: =IF(A14<=B$3, A14*B$5, (B$2-A14)*B$6) -> 382.5 | C14: =IF(A14<=B$3, B$5, -B$6) -> 153 | D14: =B14/(C14*B$4) -> 2.1588946 | E14: =A14/D14 -> 1.158
A15: 3 | B15: =IF(A15<=B$3, A15*B$5, (B$2-A15)*B$6) -> 459 | C15: =IF(A15<=B$3, B$5, -B$6) -> 153 | D15: =B15/(C15*B$4) -> 2.5906736 | E15: =A15/D15 -> 1.158
A16: 3.000001 | B16: =IF(A16<=B$3, A16*B$5, (B$2-A16)*B$6) -> 459.00015 | C16: =IF(A16<=B$3, B$5, -B$6) -> 153 | D16: =B16/(C16*B$4) -> 2.5906744 | E16: =A16/D16 -> 1.158
A17: 3.5 | B17: =IF(A17<=B$3, A17*B$5, (B$2-A17)*B$6) -> 535.5 | C17: =IF(A17<=B$3, B$5, -B$6) -> 153 | D17: =B17/(C17*B$4) -> 3.0224525 | E17: =A17/D17 -> 1.158
A18: 4 | B18: =IF(A18<=B$3, A18*B$5, (B$2-A18)*B$6) -> 612 | C18: =IF(A18<=B$3, B$5, -B$6) -> 153 | D18: =B18/(C18*B$4) -> 3.4542314 | E18: =A18/D18 -> 1.158
A19: 4.000001 | B19: =IF(A19<=B$3, A19*B$5, (B$2-A19)*B$6) -> 612.00015 | C19: =IF(A19<=B$3, B$5, -B$6) -> 153 | D19: =B19/(C19*B$4) -> 3.4542323 | E19: =A19/D19 -> 1.158
A20: 4.5 | B20: =IF(A20<=B$3, A20*B$5, (B$2-A20)*B$6) -> 688.5 | C20: =IF(A20<=B$3, B$5, -B$6) -> 153 | D20: =B20/(C20*B$4) -> 3.8860104 | E20: =A20/D20 -> 1.158
A21: 4.500001 | B21: =IF(A21<=B$3, A21*B$5, (B$2-A21)*B$6) -> 688.49985 | C21: =IF(A21<=B$3, B$5, -B$6) -> -153 | D21: =B21/(C21*B$4) -> -3.8860095 | E21: =A21/D21 -> -1.1580005
... A25: 6.5 | B25: =IF(A25<=B$3, A25*B$5, (B$2-A25)*B$6) -> 382.5 | C25: =IF(A25<=B$3, B$5, -B$6) -> -153 | D25: =B25/(C25*B$4) -> -2.1588946 | E25: =A25/D25 -> -3.0108
A26: 7 | B26: =IF(A26<=B$3, A26*B$5, (B$2-A26)*B$6) -> 306 | C26: =IF(A26<=B$3, B$5, -B$6) -> -153 | D26: =B26/(C26*B$4) -> -1.7271157 | E26: =A26/D26 -> -4.053 | P26: b | Q26: 0.3 | R26: m
A27: 7.5 | B27: =IF(A27<=B$3, A27*B$5, (B$2-A27)*B$6) -> 229.5 | C27: =IF(A27<=B$3, B$5, -B$6) -> -153 | D27: =B27/(C27*B$4) -> -1.2953368 | E27: =A27/D27 -> -5.79 | P27: h | Q27: 1.2 | R27: m
A28: 8 | B28: =IF(A28<=B$3, A28*B$5, (B$2-A28)*B$6) -> 153 | C28: =IF(A28<=B$3, B$5, -B$6) -> -153 | D28: =B28/(C28*B$4) -> -0.86355786 | E28: =A28/D28 -> -9.264 | P28: rho | Q28: 2450 | R28: kg/m3
A29: 8.5 | B29: =IF(A29<=B$3, A29*B$5, (B$2-A29)*B$6) -> 76.5 | C29: =IF(A29<=B$3, B$5, -B$6) -> -153 | D29: =B29/(C29*B$4) -> -0.43177893 | E29: =A29/D29 -> -19.686 | P29: g | Q29: 9.81 | R29: m/s^2
A30: 9 | B30: =IF(A30<=B$3, A30*B$5, (B$2-A30)*B$6) -> 0 | C30: =IF(A30<=B$3, B$5, -B$6) -> -153 | D30: =B30/(C30*B$4) -> 0 | P30: G | Q30: =Q26*Q27*Q28*Q29/1000 -> 8.65242 | R30: kN/m
P31: V_G_sup | Q31: =Q30*B2/2 -> 38.93589 | R31: kN
P32: V (1 m) | Q32: =(4.5-1)/4.5*Q31 -> 30.28347 | R32: kN
P33: V (2 m) | Q33: =(4.5-2)/4.5*Q31 -> 21.63105 | R33: kN | S33: hier ongeveer de inclined shear crack

Sheet H121
D1: P [kN] | E1: 0 | F1: 49 | G1: 49 | H1: 49 | I1: 49 | J1: 51 | K1: 52 | L1: 99 | M1: 99 | N1: 99 | O1: 124 | P1: 123 | Q1: 123 | R1: 149 | S1: 149 | T1: 148 | U1: 121 | V1: 142 | W1: 149 | X1: 149 | Y1: 149 | Z1: 172 | AA1: 172 | AB1: 172 | AC1: 175 | AD1: 173 | AE1: 173 | AF1: 157 | AG1: 189 | AH1: 198 | AI1: 198 | AJ1: 196 | AK1: 224 | AL1: 223 | AM1: 223 | AN1: 249 | AO1: 249 | AP1: 248 | AQ1: 274 | AR1: 274 | AS1: 274 | AT1: 254 | AU1: 279 | AV1: 282 | AW1: 283 | AX1: 286 | AY1: 291 | AZ1: 300 | BA1: 300 | BB1: 300 | BC1: 299 | BD1: 295 | BE1: 307 | BF1: 315 | BG1: 323 | BH1: 335 | BI1: 340 | BJ1: 341
A2: M/(Vd) | B2: x | C2: Vd/M | D2: V [kN] | E2: =30+E1*0.6666667 -> 30 | F2: =30+F1*0.6666667 -> 62.666668 | G2: =30+G1*0.6666667 -> 62.666668 | H2: =30+H1*0.6666667 -> 62.666668 | I2: =30+I1*0.6666667 -> 62.666668 | J2: =30+J1*0.6666667 -> 64.000002 | K2: =30+K1*0.6666667 -> 64.666668 | L2: =30+L1*0.6666667 -> 96.000003 | ... BJ2: =30+BJ1*0.6666667 -> 257.33334
A3: 2.1913259 | B3: =1.145*A3 -> 2.5090681 | C3: =1/A3 -> 0.45634472 | E3: 0 | F3: 0.024630225 | G3: 0.027348 | H3: 0.073345 | I3: -0.00131275 | J3: 0.0320335 | K3: 0.03378425 | L3: 0.053307 | M3: 0.05151925 | N3: 0.052804 | O3: 0.098159 | P3: 0.01197325 | Q3: 0.08697625 | R3: 0.01153825 | S3: 0.05831475 | T3: 0.0634305 | U3: 0.11634425 | V3: 0.1394535 | W3: 0.081413 | X3: 0.02883175 | Y3: 0.025813 | Z3: 0.05825675 | AA3: 0.12568275 | AB3: 0.0583825 | AC3: 0.16493375 | AD3: 0.23403675 | AE3: 0.19971975 | AF3: 0.4185715 | AG3: 0.47238225 | AH3: 0.4910625 | AI3: 0.4875475 | AJ3: 0.4017775 | AK3: 0.5245275 | AL3: 0.5321575 | AM3: 0.5773575 | AN3: 0.664705 | AO3: 0.59377 | AP3: 0.59165 | AQ3: 0.7034575 | AR3: 0.6525025 | AS3: 0.662375 | AT3: 0.6429825 | AU3: 0.709075 | AV3: 0.7102475 | AW3: 0.7152925 | AX3: 0.7895375 | AY3: 0.729195 | AZ3: 0.742265 | BA3: 0.7443075 | BB3: 0.6427275 | BC3: 0.7594275 | BD3: 0.6425875 | BE3: 0.70837 | BF3: 0.710485 | BG3: 0.7734275 | BH3: 0.757945 | BI3: 0.75151 | BJ3: 0.795675
A4: 2.1039896 | B4: =1.145*A4 -> 2.4090681 | C4: =1/A4 -> 0.47528751 | E4: 0 | F4: 0.01917075 | G4: 0.028832 | H4: 0.07174025 | I4: -0.0076335 | J4: 0.028031 | K4: 0.0381785 | L4: 0.04659575 | M4: 0.040829 | N4: 0.051011 | O4: 0.09386425 | P4: 0.006166 | Q4: 0.08274225 | R4: 0.00246325 | S4: 0.05426625 | T4: 0.05874875 | U4: 0.106784 | V4: 0.1304965 | W4: 0.07031275 | X4: 0.0200175 | Y4: 0.01621825 | Z4: 0.0466815 | AA4: 0.114649 | AB4: 0.04632925 | AC4: 0.0722 | AD4: 0.14508 | AE4: 0.1078925 | AF4: 0.339133 | AG4: 0.4100725 | AH4: 0.4241275 | AI4: 0.4295675 | AJ4: 0.34367 | AK4: 0.458845 | AL4: 0.4650425 | AM4: 0.51636 | AN4: 0.5929925 | AO4: 0.52157 | AP4: 0.521155 | AQ4: 0.630015 | AR4: 0.5806925 | AS4: 0.5847775 | AT4: 0.57421 | AU4: 0.638595 | AV4: 0.6339125 | AW4: 0.639845 | AX4: 0.718225 | AY4: 0.6520875 | AZ4: 0.663225 | BA4: 0.665455 | BB4: 0.5583675 | BC4: 0.683285 | BD4: 0.56226 | BE4: 0.63109 | BF4: 0.627395 | BG4: 0.6857475 | BH4: 0.6607225 | BI4: 0.661595 | BJ4: 0.7028075
A5: 2.0166534 | B5: =1.145*A5 -> 2.3090681 | C5: =1/A5 -> 0.49587103 | E5: 0 | F5: 0.0213205 | G5: 0.0322905 | H5: 0.07741525 | I5: -0.0124325 | J5: 0.03251225 | K5: 0.03444 | L5: 0.04800025 | M5: 0.04098875 | N5: 0.04941175 | O5: 0.0913815 | P5: 0.0008545 | Q5: 0.085194 | R5: -0.00905875 | S5: 0.047416 | T5: 0.048935 | U5: 0.10319225 | V5: 0.1271105 | W5: 0.064872 | X5: 0.00868025 | Y5: 0.00648725 | Z5: 0.03457575 | AA5: 0.10307975 | AB5: 0.0337725 | AC5: 0.047585 | AD5: 0.109265 | AE5: 0.0664675 | AF5: 0.2954275 | AG5: 0.366345 | AH5: 0.3893575 | AI5: 0.386535 | AJ5: 0.29007 | AK5: 0.4130425 | AL5: 0.41556 | AM5: 0.47377 | AN5: 0.534905 | AO5: 0.464775 | AP5: 0.4623625 | AQ5: 0.57381 | AR5: 0.5249 | AS5: 0.5238125 | AT5: 0.5259225 | AU5: 0.5901425 | AV5: 0.58832 | AW5: 0.5895525 | AX5: 0.673195 | AY5: 0.6005675 | AZ5: 0.609525 | BA5: 0.61211 | BB5: 0.5017075 | BC5: 0.6304625 | BD5: 0.500685 | BE5: 0.5735325 | BF5: 0.5655075 | BG5: 0.6260975 | BH5: 0.5888925 | BI5: 0.597055 | BJ5: 0.6397625
A6: 1.9293171 | B6: =1.145*A6 -> 2.2090681 | C6: =1/A6 -> 0.5183181 | E6: 0 | F6: 0.01343125 | G6: 0.0268535 | H6: 0.0713405 | I6: -0.0238185 | J6: 0.0270105 | K6: 0.0227915 | L6: 0.03553075 | M6: 0.03435125 | N6: 0.0349215 | O6: 0.0793405 | P6: -0.01162925 | Q6: 0.07350075 | R6: -0.02176175 | S6: 0.03202175 | T6: 0.03489625 | U6: 0.08781525 | V6: 0.11438125 | W6: 0.0497665 | X6: -0.01037475 | Y6: -0.014138 | Z6: 0.00818025 | AA6: 0.08460875 | AB6: 0.01024975 | AC6: 0.016055 | AD6: 0.070205 | AE6: 0.0245475 | AF6: 0.24604 | AG6: 0.3196475 | AH6: 0.33978 | AI6: 0.3400325 | AJ6: 0.2416425 | AK6: 0.385965 | AL6: 0.3848725 | AM6: 0.450105 | AN6: 0.5142025 | AO6: 0.44015 | AP6: 0.4447675 | AQ6: 0.54436 | AR6: 0.494055 | AS6: 0.491 | AT6: 0.491925 | AU6: 0.55276 | AV6: 0.552775 | AW6: 0.55274 | AX6: 0.636185 | AY6: 0.567385 | AZ6: 0.5699725 | BA6: 0.5763925 | BB6: 0.4596375 | BC6: 0.592825 | BD6: 0.45723 | BE6: 0.5362875 | BF6: 0.5251175 | BG6: 0.58839 | BH6: 0.5426625 | BI6: 0.553435 | BJ6: 0.6009175
A7: 1.8419809 | B7: =1.145*A7 -> 2.1090681 | C7: =1/A7 -> 0.54289379 | E7: 0 | F7: 0.01466375 | G7: 0.0255235 | H7: 0.0639645 | I7: -0.02578475 | J7: 0.028045 | K7: 0.0179555 | L7: 0.03066425 | M7: 0.0326955 | N7: 0.0364275 | O7: 0.078459 | P7: -0.0213035 | Q7: 0.071016 | R7: -0.02781375 | S7: 0.0220095 | T7: 0.02640625 | U7: 0.079876 | V7: 0.1073775 | W7: 0.039123 | X7: -0.026551 | Y7: -0.03202175 | Z7: -0.0079985 | AA7: 0.07450125 | AB7: -0.003746 | AC7: -0.0021175 | AD7: 0.0550225 | AE7: 0.00734 | AF7: 0.2311175 | AG7: 0.3043875 | AH7: 0.321725 | AI7: 0.322855 | AJ7: 0.21177 | AK7: 0.3551 | AL7: 0.354515 | AM7: 0.42491 | AN7: 0.484265 | AO7: 0.4052725 | AP7: 0.414015 | AQ7: 0.506805 | AR7: 0.45641 | AS7: 0.447 | AT7: 0.449635 | AU7: 0.5123075 | AV7: 0.51473 | AW7: 0.513585 | AX7: 0.60054 | AY7: 0.52209 | AZ7: 0.5289825 | BA7: 0.53553 | BB7: 0.4150275 | BC7: 0.5495125 | BD7: 0.41253 | BE7: 0.48221 | BF7: 0.46587 | BG7: 0.5408425 | BH7: 0.493115 | BI7: 0.4992875 | BJ7: 0.5529
A8: 1.7546447 | B8: =1.145*A8 -> 2.0090681 | C8: =1/A8 -> 0.56991596 | E8: 0 | F8: 0.0283185 | G8: 0.033795 | H8: 0.083949 | I8: -0.00649275 | J8: 0.04809875 | K8: 0.0315525 | L8: 0.0398105 | M8: 0.05390425 | N8: 0.046065 | O8: 0.10098475 | P8: -0.02416975 | Q8: 0.08362375 | R8: -0.02470375 | S8: 0.0285815 | T8: 0.024877 | U8: 0.09152225 | V8: 0.115582 | W8: 0.0412955 | X8: -0.0270925 | Y8: -0.03783175 | Z8: -0.01330575 | AA8: 0.075122 | AB8: -0.009939 | AC8: -0.0141875 | AD8: 0.0494325 | AE8: -0.002865 | AF8: 0.21658 | AG8: 0.28701 | AH8: 0.2883925 | AI8: 0.3024375 | AJ8: 0.18387 | AK8: 0.3287775 | AL8: 0.32755 | AM8: 0.4062225 | AN8: 0.4514375 | AO8: 0.3781975 | AP8: 0.377675 | AQ8: 0.488155 | AR8: 0.4334675 | AS8: 0.4183425 | AT8: 0.498495 | AU8: 0.58053 | AV8: 0.5869475 | AW8: 0.5853625 | AX8: 0.686065 | AY8: 0.5949225 | AZ8: 0.6146275 | BA8: 0.614685 | BB8: 0.49312 | BC8: 0.63647 | BD8: 0.492055 | BE8: 0.5665475 | BF8: 0.5396525 | BG8: 0.639565 | BH8: 0.5997 | BI8: 0.6171525 | BJ8: 0.688795
A9: 1.6673084 | B9: =1.145*A9 -> 1.9090681 | C9: =1/A9 -> 0.59976906 | E9: 0 | F9: 0.03087475 | G9: 0.0252085 | H9: 0.08939875 | I9: -0.0140675 | J9: 0.04604575 | K9: 0.03388475 | L9: 0.04185775 | M9: 0.052128 | N9: 0.0491265 | O9: 0.107895 | P9: -0.0351 | Q9: 0.092841 | R9: -0.04694875 | S9: 0.0255465 | T9: 0.01909325 | U9: 0.09792425 | V9: 0.124899 | W9: 0.03564525 | X9: -0.0456405 | Y9: -0.05591025 | Z9: -0.0338165 | AA9: 0.07025 | AB9: -0.0308055 | AC9: -0.0387025 | AD9: 0.03471 | AE9: -0.0266175 | AF9: 0.1030175 | AG9: 0.146175 | AH9: 0.1516525 | AI9: 0.1535325 | AJ9: 0.025655 | AK9: 0.1504825 | AL9: 0.1472575 | AM9: 0.2400525 | AN9: 0.26238 | AO9: 0.1781925 | AP9: 0.17882 | AQ9: 0.2808 | AR9: 0.214655 | AS9: 0.199845 | AT9: 0.31838 | AU9: 0.4094575 | AV9: 0.4203775 | AW9: 0.414775 | AX9: 0.543735 | AY9: 0.4331 | AZ9: 0.4530525 | BA9: 0.45673 | BB9: 0.30553 | BC9: 0.478095 | BD9: 0.305965 | BE9: 0.393285 | BF9: 0.3593025 | BG9: 0.46756 | BH9: 0.4272325 | BI9: 0.445465 | BJ9: 0.5359525
A10: 1.5799722 | B10: =1.145*A10 -> 1.8090681 | C10: =1/A10 -> 0.63292254 | E10: 0 | F10: 0.045588 | G10: 0.03241575 | H10: 0.10870025 | I10: -0.010316 | J10: 0.06287125 | K10: 0.04018 | L10: 0.04295825 | M10: 0.05551375 | N10: 0.04901975 | O10: 0.12681625 | P10: -0.03761625 | Q10: 0.1070815 | R10: -0.05609925 | S10: 0.03261775 | T10: 0.029072 | U10: 0.114769 | V10: 0.14762025 | W10: 0.04301225 | X10: -0.055745 | Y10: -0.06618525 | Z10: -0.0419405 | AA10: 0.08179375 | AB10: -0.0422895 | AC10: -0.0539225 | AD10: 0.0322925 | AE10: -0.0410175 | AF10: 0.106995 | AG10: 0.136545 | AH10: 0.1402125 | AI10: 0.1447525 | AJ10: -0.0142 | AK10: 0.12894 | AL10: 0.125035 | AM10: 0.2353825 | AN10: 0.253555 | AO10: 0.14675 | AP10: 0.1415675 | AQ10: 0.2527475 | AR10: 0.1711275 | AS10: 0.161905 | AT10: 0.3000375 | AU10: 0.4359025 | AV10: 0.44949 | AW10: 0.439705 | AX10: 0.5961575 | AY10: 0.4846825 | AZ10: 0.51999 | BA10: 0.523955 | BB10: 0.350505 | BC10: 0.55409 | BD10: 0.35642 | BE10: 0.453505 | BF10: 0.416025 | BG10: 0.5370125 | BH10: 0.4933975 | BI10: 0.5138725 | BJ10: 0.6138875
D24: =D1 -> P [kN] | E24: =MAX($E1:E1) -> 0 | F24: =MAX($E1:F1) -> 49 | G24: =MAX($E1:G1) -> 49 | H24: =MAX($E1:H1) -> 49 | I24: =MAX($E1:I1) -> 49 | J24: =MAX($E1:J1) -> 51 | K24: =MAX($E1:K1) -> 52 | L24: =MAX($E1:L1) -> 99 | ... BJ24: =MAX($E1:BJ1) -> 341
A25: =A2 -> M/(Vd) | B25: =B2 -> x | C25: =C2 -> Vd/M | D25: =D2 -> V [kN] | E25: =MAX($E2:E2) -> 30 | F25: =MAX($E2:F2) -> 62.666668 | G25: =MAX($E2:G2) -> 62.666668 | H25: =MAX($E2:H2) -> 62.666668 | I25: =MAX($E2:I2) -> 62.666668 | J25: =MAX($E2:J2) -> 64.000002 | K25: =MAX($E2:K2) -> 64.666668 | L25: =MAX($E2:L2) -> 96.000003 | ... BJ25: =MAX($E2:BJ2) -> 257.33334
A26: =A3 -> 2.1913259 | B26: =B3 -> 2.5090681 | C26: =C3 -> 0.45634472 | E26: =MAX($E3:E3) -> 0 | F26: =MAX($E3:F3) -> 0.024630225 | G26: =MAX($E3:G3) -> 0.027348 | H26: =MAX($E3:H3) -> 0.073345 | I26: =MAX($E3:I3) -> 0.073345 | J26: =MAX($E3:J3) -> 0.073345 | K26: =MAX($E3:K3) -> 0.073345 | L26: =MAX($E3:L3) -> 0.073345 | ... BJ26: =MAX($E3:BJ3) -> 0.795675
A27: =A4 -> 2.1039896 | B27: =B4 -> 2.4090681 | C27: =C4 -> 0.47528751 | E27: =MAX($E4:E4) -> 0 | F27: =MAX($E4:F4) -> 0.01917075 | G27: =MAX($E4:G4) -> 0.028832 | H27: =MAX($E4:H4) -> 0.07174025 | I27: =MAX($E4:I4) -> 0.07174025 | J27: =MAX($E4:J4) -> 0.07174025 | K27: =MAX($E4:K4) -> 0.07174025 | L27: =MAX($E4:L4) -> 0.07174025 | ... BJ27: =MAX($E4:BJ4) -> 0.718225
A28: =A5 -> 2.0166534 | B28: =B5 -> 2.3090681 | C28: =C5 -> 0.49587103 | E28: =MAX($E5:E5) -> 0 | F28: =MAX($E5:F5) -> 0.0213205 | G28: =MAX($E5:G5) -> 0.0322905 | H28: =MAX($E5:H5) -> 0.07741525 | I28: =MAX($E5:I5) -> 0.07741525 | J28: =MAX($E5:J5) -> 0.07741525 | K28: =MAX($E5:K5) -> 0.07741525 | L28: =MAX($E5:L5) -> 0.07741525 | ... BJ28: =MAX($E5:BJ5) -> 0.673195
A29: =A6 -> 1.9293171 | B29: =B6 -> 2.2090681 | C29: =C6 -> 0.5183181 | E29: =MAX($E6:E6) -> 0 | F29: =MAX($E6:F6) -> 0.01343125 | G29: =MAX($E6:G6) -> 0.0268535 | H29: =MAX($E6:H6) -> 0.0713405 | I29: =MAX($E6:I6) -> 0.0713405 | J29: =MAX($E6:J6) -> 0.0713405 | K29: =MAX($E6:K6) -> 0.0713405 | L29: =MAX($E6:L6) -> 0.0713405 | ... BJ29: =MAX($E6:BJ6) -> 0.636185
A30: =A7 -> 1.8419809 | B30: =B7 -> 2.1090681 | C30: =C7 -> 0.54289379 | E30: =MAX($E7:E7) -> 0 | F30: =MAX($E7:F7) -> 0.01466375 | G30: =MAX($E7:G7) -> 0.0255235 | H30: =MAX($E7:H7) -> 0.0639645 | I30: =MAX($E7:I7) -> 0.0639645 | J30: =MAX($E7:J7) -> 0.0639645 | K30: =MAX($E7:K7) -> 0.0639645 | L30: =MAX($E7:L7) -> 0.0639645 | ... BJ30: =MAX($E7:BJ7) -> 0.60054
A31: =A8 -> 1.7546447 | B31: =B8 -> 2.0090681 | C31: =C8 -> 0.56991596 | E31: =MAX($E8:E8) -> 0 | F31: =MAX($E8:F8) -> 0.0283185 | G31: =MAX($E8:G8) -> 0.033795 | H31: =MAX($E8:H8) -> 0.083949 | I31: =MAX($E8:I8) -> 0.083949 | J31: =MAX($E8:J8) -> 0.083949 | K31: =MAX($E8:K8) -> 0.083949 | L31: =MAX($E8:L8) -> 0.083949 | ... BJ31: =MAX($E8:BJ8) -> 0.688795
A32: =A9 -> 1.6673084 | B32: =B9 -> 1.9090681 | C32: =C9 -> 0.59976906 | E32: =MAX($E9:E9) -> 0 | F32: =MAX($E9:F9) -> 0.03087475 | G32: =MAX($E9:G9) -> 0.03087475 | H32: =MAX($E9:H9) -> 0.08939875 | I32: =MAX($E9:I9) -> 0.08939875 | J32: =MAX($E9:J9) -> 0.08939875 | K32: =MAX($E9:K9) -> 0.08939875 | L32: =MAX($E9:L9) -> 0.08939875 | ... BJ32: =MAX($E9:BJ9) -> 0.543735
A33: =A10 -> 1.5799722 | B33: =B10 -> 1.8090681 | C33: =C10 -> 0.63292254 | E33: =MAX($E10:E10) -> 0 | F33: =MAX($E10:F10) -> 0.045588 | G33: =MAX($E10:G10) -> 0.045588 | H33: =MAX($E10:H10) -> 0.10870025 | I33: =MAX($E10:I10) -> 0.10870025 | J33: =MAX($E10:J10) -> 0.10870025 | K33: =MAX($E10:K10) -> 0.10870025 | L33: =MAX($E10:L10) -> 0.10870025 | ... BJ33: =MAX($E10:BJ10) -> 0.6138875
D47: w_max | E47: =MAX(E26:E45) -> 0 | F47: =MAX(F26:F45) -> 0.045588 | G47: =MAX(G26:G45) -> 0.045588 | H47: =MAX(H26:H45) -> 0.10870025 | I47: =MAX(I26:I45) -> 0.10870025 | J47: =MAX(J26:J45) -> 0.10870025 | K47: =MAX(K26:K45) -> 0.10870025 | L47: =MAX(L26:L45) -> 0.10870025 | ... BJ47: =MAX(BJ26:BJ45) -> 0.795675 | BK47: 10
D48: w_max,w | E48: {=MAX($C26:$C45*E26:E45)} -> 0 | F48: {=MAX($C26:$C45*F26:F45)} -> 0.028853673 | G48: {=MAX($C26:$C45*G26:G45)} -> 0.028853673 | H48: {=MAX($C26:$C45*H26:H45)} -> 0.068798838 | I48: {=MAX($C26:$C45*I26:I45)} -> 0.068798838 | J48: {=MAX($C26:$C45*J26:J45)} -> 0.068798838 | K48: {=MAX($C26:$C45*K26:K45)} -> 0.068798838 | L48: {=MAX($C26:$C45*L26:L45)} -> 0.068798838 | ... BJ48: {=MAX($C26:$C45*BJ26:BJ45)} -> 0.39255527 | BK48: 10
D49: V_u/V | E49: =MAX($E25:$BJ25)/E25 -> 8.5777782 | F49: =MAX($E25:$BJ25)/F25 -> 4.1063831 | G49: =MAX($E25:$BJ25)/G25 -> 4.1063831 | H49: =MAX($E25:$BJ25)/H25 -> 4.1063831 | I49: =MAX($E25:$BJ25)/I25 -> 4.1063831 | J49: =MAX($E25:$BJ25)/J25 -> 4.0208334 | K49: =MAX($E25:$BJ25)/K25 -> 3.9793815 | L49: =MAX($E25:$BJ25)/L25 -> 2.6805556 | ... BJ49: =MAX($E25:$BJ25)/BJ25 -> 1 | BK49: 1
D50: V/V_u | E50: =E25/MAX($E25:$BJ25) -> 0.11658031 | F50: =F25/MAX($E25:$BJ25) -> 0.24352331 | G50: =G25/MAX($E25:$BJ25) -> 0.24352331 | H50: =H25/MAX($E25:$BJ25) -> 0.24352331 | I50: =I25/MAX($E25:$BJ25) -> 0.24352331 | J50: =J25/MAX($E25:$BJ25) -> 0.24870466 | K50: =K25/MAX($E25:$BJ25) -> 0.25129533 | L50: =L25/MAX($E25:$BJ25) -> 0.37305699 | ... BJ50: =BJ25/MAX($E25:$BJ25) -> 1

Sheet H401
D1: P [kN] | E1: 0 | F1: 50 | G1: 51 | H1: 51 | I1: 91 | J1: 91 | K1: 93 | L1: 98 | M1: 100 | N1: 100 | O1: 101 | P1: 127 | Q1: 135 | R1: 136 | S1: 136 | T1: 137 | U1: 137 | V1: 145 | W1: 149 | X1: 149 | Y1: 176 | Z1: 176 | AA1: 177 | AB1: 183 | AC1: 184 | AD1: 184 | AE1: 186 | AF1: 201 | AG1: 202 | AH1: 203 | AI1: 217 | AJ1: 220 | AK1: 221 | AL1: 222 | AM1: 223 | AN1: 223 | AO1: 223 | AP1: 225 | AQ1: 225 | AR1: 226 | AS1: 226 | AT1: 227 | AU1: 238 | AV1: 238 | AW1: 238 | AX1: 240 | AY1: 245 | AZ1: 246 | BA1: 252 | BB1: 253 | BC1: 253 | BD1: 255 | BE1: 258 | BF1: 259 | BG1: 263 | BH1: 263
A2: M/(Vd) | B2: x | C2: Vd/M | D2: V [kN] | E2: =30+E1/2 -> 30 | F2: =30+F1/2 -> 55 | G2: =30+G1/2 -> 55.5 | H2: =30+H1/2 -> 55.5 | I2: =30+I1/2 -> 75.5 | J2: =30+J1/2 -> 75.5 | K2: =30+K1/2 -> 76.5 | L2: =30+L1/2 -> 79 | ... BH2: =30+BH1/2 -> 161.5
A3: 3.5663212 | B3: =1.158*A3 -> 4.1298 | C3: =1/A3 -> 0.28040099 | E3: 0 | F3: 0.0227154 | G3: 0.1603122 | H3: -0.0220306 | I3: -0.16310275 | J3: -0.1486375 | K3: -0.03696575 | L3: -0.007909 | M3: 0.00047675 | N3: 0.003631325 | O3: -0.0319745 | P3: 0.1837805 | Q3: 0.621313 | R3: 0.512935 | S3: 0.5836425 | T3: 0.200325 | U3: 0.05572 | V3: 0.00662 | W3: 0.1383225 | X3: 0.232115 | Y3: 0.9648025 | Z3: 0.996765 | AA3: 1.118915 | AB3: 1.3857575 | AC3: 1.2557475 | AD3: 1.325551 | AE3: 1.2981653 | AF3: 1.3842975 | AG3: 1.3406525 | AH3: 1.38464 | AI3: 1.3376625 | AJ3: 1.510575 | AK3: 1.52605 | AL3: 1.37895 | AM3: 1.555745 | AN3: 1.5669475 | AO3: 1.5676925 | AP3: 1.5623825 | AQ3: 1.5598975 | AR3: 1.4574525 | AS3: 1.530155 | AT3: 1.5005375 | AU3: 1.609565 | AV3: 1.6604725 | AW3: 1.6683375 | AX3: 1.6431925 | AY3: 1.6856075 | AZ3: 1.678425 | BA3: 1.76557 | BB3: 1.77374 | BC3: 1.76547 | BD3: 1.797925 | BE3: 1.809865 | BF3: 1.801725 | BG3: 1.621955 | BH3: 1.81375
A4: 3.4799655 | B4: =1.158*A4 -> 4.0298 | C4: =1/A4 -> 0.28735917 | E4: 0 | F4: 0.02485995 | G4: 0.14192503 | H4: -0.0117529 | I4: -0.14242125 | J4: -0.13255675 | K4: -0.038324 | L4: -0.0072575 | M4: -0.000100575 | N4: 0.00382125 | O4: -0.025484 | P4: 0.16671825 | Q4: 0.50819 | R4: 0.4146875 | S4: 0.47397 | T4: 0.14411 | U4: 0.0148925 | V4: 0.009 | W4: 0.12445 | X4: 0.204137 | Y4: 0.8669775 | Z4: 0.8953175 | AA4: 0.998885 | AB4: 1.2563 | AC4: 1.1459525 | AD4: 1.2020375 | AE4: 1.1789175 | AF4: 1.26226 | AG4: 1.224735 | AH4: 1.25749 | AI4: 1.216995 | AJ4: 1.3646625 | AK4: 1.3818 | AL4: 1.2526925 | AM4: 1.4038925 | AN4: 1.414235 | AO4: 1.41586 | AP4: 1.413955 | AQ4: 1.4094575 | AR4: 1.3261 | AS4: 1.386775 | AT4: 1.3603175 | AU4: 1.4520825 | AV4: 1.4973925 | AW4: 1.50086 | AX4: 1.47834 | AY4: 1.5151975 | AZ4: 1.508395 | BA4: 1.588105 | BB4: 1.593515 | BC4: 1.5874425 | BD4: 1.618065 | BE4: 1.6255125 | BF4: 1.6199475 | BG4: 1.4578825 | BH4: 1.6304875
A5: 3.3936097 | B5: =1.158*A5 -> 3.9298 | C5: =1/A5 -> 0.29467148 | E5: 0 | F5: 0.025106075 | G5: 0.13579648 | H5: -0.0086451 | I5: -0.12916725 | J5: -0.117086 | K5: -0.03147225 | L5: -0.00588825 | M5: 0.00087 | N5: -0.00216995 | O5: -0.02207475 | P5: 0.155393 | Q5: 0.4393775 | R5: 0.3557 | S5: 0.411205 | T5: 0.1371825 | U5: 0.01886 | V5: 0.003715 | W5: 0.11226 | X5: 0.187208 | Y5: 0.7960325 | Z5: 0.8208275 | AA5: 0.91652 | AB5: 1.179485 | AC5: 1.082235 | AD5: 1.1312475 | AE5: 1.1059 | AF5: 1.19097 | AG5: 1.1603775 | AH5: 1.1846475 | AI5: 1.14383 | AJ5: 1.28533 | AK5: 1.3019775 | AL5: 1.1866925 | AM5: 1.3268075 | AN5: 1.3314525 | AO5: 1.3353075 | AP5: 1.3314575 | AQ5: 1.33042 | AR5: 1.259075 | AS5: 1.3094325 | AT5: 1.287305 | AU5: 1.3796825 | AV5: 1.41357 | AW5: 1.4217 | AX5: 1.3981825 | AY5: 1.42953 | AZ5: 1.426675 | BA5: 1.50199 | BB5: 1.508515 | BC5: 1.501595 | BD5: 1.5274375 | BE5: 1.5377275 | BF5: 1.5343825 | BG5: 1.3860125 | BH5: 1.5397725
A6: 3.3072539 | B6: =1.158*A6 -> 3.8298 | C6: =1/A6 -> 0.30236566 | E6: 0 | F6: 0.024103375 | G6: 0.13046188 | H6: -0.00411615 | I6: -0.11287075 | J6: -0.10252775 | K6: -0.02118325 | L6: -0.00111925 | M6: 0.001662825 | N6: -0.0025896 | O6: -0.0149015 | P6: 0.1486795 | Q6: 0.406875 | R6: 0.3347825 | S6: 0.3823825 | T6: 0.13146 | U6: 0.019065 | V6: 0.002495 | W6: 0.104915 | X6: 0.17546775 | Y6: 0.764035 | Z6: 0.786045 | AA6: 0.8721725 | AB6: 1.3385175 | AC6: 1.2561225 | AD6: 1.3031375 | AE6: 1.2583125 | AF6: 1.4052725 | AG6: 1.3786175 | AH6: 1.40358 | AI6: 1.38197 | AJ6: 1.5293775 | AK6: 1.543995 | AL6: 1.442075 | AM6: 1.5821975 | AN6: 1.5880725 | AO6: 1.594665 | AP6: 1.57829 | AQ6: 1.581515 | AR6: 1.525 | AS6: 1.5648775 | AT6: 1.54933 | AU6: 1.66781 | AV6: 1.693715 | AW6: 1.6987825 | AX6: 1.66863 | AY6: 1.7084925 | AZ6: 1.7064 | BA6: 1.7798275 | BB6: 1.787785 | BC6: 1.7778875 | BD6: 1.79857 | BE6: 1.80868 | BF6: 1.80711 | BG6: 1.672355 | BH6: 1.8078675
A7: 3.2208981 | B7: =1.158*A7 -> 3.7298 | C7: =1/A7 -> 0.31047241 | E7: 0 | F7: 0.0255173 | G7: 0.13230312 | H7: 0.0005654 | I7: -0.091791 | J7: -0.08605425 | K7: -0.0085075 | L7: 0.00345675 | M7: 0.00037915 | N7: -0.0020122 | O7: -0.014071 | P7: 0.148153 | Q7: 0.395425 | R7: 0.33309 | S7: 0.3755575 | T7: 0.1303825 | U7: 0.0210425 | V7: 0.0030775 | W7: 0.10225 | X7: 0.1695275 | Y7: 0.7440975 | Z7: 0.76589 | AA7: 0.8478925 | AB7: 1.4183875 | AC7: 1.346125 | AD7: 1.3921175 | AE7: 1.3252975 | AF7: 1.52292 | AG7: 1.4956875 | AH7: 1.5185225 | AI7: 1.4968825 | AJ7: 1.6448525 | AK7: 1.65821 | AL7: 1.5652225 | AM7: 1.6968325 | AN7: 1.696435 | AO7: 1.70412 | AP7: 1.6908275 | AQ7: 1.6913925 | AR7: 1.6525275 | AS7: 1.6792525 | AT7: 1.6708875 | AU7: 1.79143 | AV7: 1.8077375 | AW7: 1.8108925 | AX7: 1.7862275 | AY7: 1.82313 | AZ7: 1.82289 | BA7: 1.8884775 | BB7: 1.8985925 | BC7: 1.8891325 | BD7: 1.90635 | BE7: 1.9143675 | BF7: 1.9170925 | BG7: 1.78932 | BH7: 1.916065
A8: 3.1345423 | B8: =1.158*A8 -> 3.6298 | C8: =1/A8 -> 0.31902584 | E8: 0 | F8: 0.0210364 | G8: 0.13178857 | H8: 0.00880185 | I8: -0.0714515 | J8: -0.07082575 | K8: 0.00073025 | L8: 0.01128825 | M8: -0.000223625 | N8: 0.002786 | O8: -0.0072355 | P8: 0.148563 | Q8: 0.265245 | R8: 0.21488 | S8: 0.2500575 | T8: 0.13301 | U8: 0.0251575 | V8: 0.0046225 | W8: 0.10334 | X8: 0.17179 | Y8: 0.4881625 | Z8: 0.50990667 | AA8: 0.58625417 | AB8: 1.128355 | AC8: 1.0617975 | AD8: 1.0993967 | AE8: 1.0317975 | AF8: 1.2522933 | AG8: 1.2320567 | AH8: 1.2500158 | AI8: 1.2413783 | AJ8: 1.3920417 | AK8: 1.404175 | AL8: 1.3202517 | AM8: 1.4407317 | AN8: 1.4345625 | AO8: 1.4475992 | AP8: 1.4293842 | AQ8: 1.427135 | AR8: 1.4061383 | AS8: 1.4264417 | AT8: 1.4228775 | AU8: 1.5243608 | AV8: 1.5344442 | AW8: 1.5356983 | AX8: 1.5113233 | AY8: 1.5452075 | AZ8: 1.5471533 | BA8: 1.5998783 | BB8: 1.6092725 | BC8: 1.5993725 | BD8: 1.6222008 | BE8: 1.6302592 | BF8: 1.6414025 | BG8: 1.52523 | BH8: 1.6106958
A9: 3.0481865 | B9: =1.158*A9 -> 3.5298 | C9: =1/A9 -> 0.32806391 | E9: 0 | F9: 0.02476305 | G9: 0.136351 | H9: 0.01598215 | I9: -0.05195525 | J9: -0.053358 | K9: 0.01816775 | L9: 0.02231275 | M9: 0.005419025 | N9: 0.009836425 | O9: 0.0009985 | P9: 0.15545975 | Q9: 0.084915 | R9: 0.0567125 | S9: 0.080465 | T9: 0.143245 | U9: 0.03702 | V9: 0.010975 | W9: 0.1070575 | X9: 0.176225 | Y9: 0.32375 | Z9: 0.34668 | AA9: 0.4179025 | AB9: 0.9532125 | AC9: 0.885785 | AD9: 0.92485 | AE9: 0.8488075 | AF9: 1.201235 | AG9: 1.18245 | AH9: 1.1994375 | AI9: 1.2454225 | AJ9: 1.419825 | AK9: 1.4299075 | AL9: 1.3513425 | AM9: 1.472955 | AN9: 1.4624025 | AO9: 1.4743225 | AP9: 1.4546325 | AQ9: 1.45573 | AR9: 1.45026 | AS9: 1.4565425 | AT9: 1.4564025 | AU9: 1.57047 | AV9: 1.5708575 | AW9: 1.5723375 | AX9: 1.544785 | AY9: 1.57622 | AZ9: 1.5833675 | BA9: 1.641965 | BB9: 1.648845 | BC9: 1.6420025 | BD9: 1.6828025 | BE9: 1.7002675 | BF9: 1.7157275 | BG9: 1.6108325 | BH9: 1.646475
A10: 2.9618307 | B10: =1.158*A10 -> 3.4298 | C10: =1/A10 -> 0.33762902 | E10: 0 | F10: 0.023636575 | G10: 0.13995727 | H10: 0.02018345 | I10: -0.03394525 | J10: -0.04124875 | K10: 0.0334875 | L10: 0.0315875 | M10: 0.005420725 | N10: 0.007500075 | O10: 0.0064925 | P10: 0.16271725 | Q10: 0.0712125 | R10: 0.05068 | S10: 0.0673225 | T10: 0.1501125 | U10: 0.044395 | V10: 0.0112625 | W10: 0.10639 | X10: 0.175525 | Y10: 0.31068 | Z10: 0.33375 | AA10: 0.395855 | AB10: 0.9396475 | AC10: 0.8778975 | AD10: 0.910255 | AE10: 0.8292325 | AF10: 1.1805275 | AG10: 1.1661875 | AH10: 1.17645 | AI10: 1.24539 | AJ10: 1.4414825 | AK10: 1.446665 | AL10: 1.37526 | AM10: 1.50626 | AN10: 1.49477 | AO10: 1.5032825 | AP10: 1.47399 | AQ10: 1.4799275 | AR10: 1.4901925 | AS10: 1.4909525 | AT10: 1.49485 | AU10: 1.6174325 | AV10: 1.6109025 | AW10: 1.611065 | AX10: 1.58347 | AY10: 1.6119375 | AZ10: 1.6218475 | BA10: 1.6269733 | BB10: 1.6319042 | BC10: 1.6253933 | BD10: 1.6653717 | BE10: 1.6858767 | BF10: 1.6996233 | BG10: 1.6002408 | BH10: 1.6551458
A11: 2.875475 | B11: =1.158*A11 -> 3.3298 | C11: =1/A11 -> 0.34776863 | E11: 0 | F11: 0.021477125 | G11: 0.1357674 | H11: 0.023406225 | I11: -0.012236 | J11: -0.025215 | K11: 0.04663175 | L11: 0.03946225 | M11: 0.009209875 | N11: 0.011647375 | O11: 0.013998 | P11: 0.16480625 | Q11: 0.06432 | R11: 0.0614175 | S11: 0.0726925 | T11: 0.1545225 | U11: 0.05066 | V11: 0.0110775 | W11: 0.10662 | X11: 0.1735675 | Y11: 0.1006275 | Z11: 0.12039 | AA11: 0.1764625 | AB11: 0.700785 | AC11: 0.64681 | AD11: 0.670715 | AE11: 0.5898225 | AF11: 0.95175 | AG11: 0.94277 | AH11: 0.9521525 | AI11: 1.1009725 | AJ11: 1.3194408 | AK11: 1.3284033 | AL11: 1.26461 | AM11: 1.4081908 | AN11: 1.3984033 | AO11: 1.4087825 | AP11: 1.359615 | AQ11: 1.3716283 | AR11: 1.4029658 | AS11: 1.393135 | AT11: 1.4005917 | AU11: 1.5362075 | AV11: 1.5235292 | AW11: 1.5210075 | AX11: 1.4870783 | AY11: 1.5162158 | AZ11: 1.532155 | BA11: 1.59687 | BB11: 1.5984233 | BC11: 1.5941467 | BD11: 1.6421667 | BE11: 1.6727233 | BF11: 1.6940067 | BG11: 1.6313167 | BH11: 1.8312933
A12: 2.7891192 | B12: =1.158*A12 -> 3.2298 | C12: =1/A12 -> 0.35853613 | E12: 0 | F12: 0.016847425 | G12: 0.12990252 | H12: 0.017910075 | I12: -0.00515475 | J12: -0.01828475 | K12: 0.05403375 | L12: 0.043336 | M12: 0.003546275 | N12: 0.007227875 | O12: 0.00957475 | P12: 0.163183 | Q12: 0.0487075 | R12: 0.0651125 | S12: 0.06466 | T12: 0.1531 | U12: 0.049935 | V12: 0.00275 | W12: 0.1009725 | X12: 0.170275 | Y12: -0.0021875 | Z12: 0.0188825 | AA12: 0.0724775 | AB12: 0.4800075 | AC12: 0.4334375 | AD12: 0.4494 | AE12: 0.3613425 | AF12: 0.7136275 | AG12: 0.7142225 | AH12: 0.7180625 | AI12: 0.8677225 | AJ12: 1.115885 | AK12: 1.12184 | AL12: 1.0642975 | AM12: 1.20086 | AN12: 1.191925 | AO12: 1.196995 | AP12: 1.1416575 | AQ12: 1.15665 | AR12: 1.2062175 | AS12: 1.1881375 | AT12: 1.20238 | AU12: 1.3321975 | AV12: 1.3106375 | AW12: 1.3087875 | AX12: 1.2712275 | AY12: 1.29705 | AZ12: 1.31488 | BA12: 1.3598675 | BB12: 1.36632 | BC12: 1.3573325 | BD12: 1.4033375 | BE12: 1.4281575 | BF12: 1.45065 | BG12: 1.394295 | BH12: 1.5789975
A13: 2.7027634 | B13: =1.158*A13 -> 3.1298 | C13: =1/A13 -> 0.36999169 | E13: 0 | F13: 0.011910075 | G13: 0.13243835 | H13: 0.017515525 | I13: -0.00065725 | J13: -0.00637725 | K13: 0.0647685 | L13: 0.05061775 | M13: 0.00071305 | N13: 0.003133 | O13: 0.009416 | P13: 0.162692 | Q13: 0.040885 | R13: 0.06927 | S13: 0.059045 | T13: 0.155545 | U13: 0.05011 | V13: -0.005365 | W13: 0.0953225 | X13: 0.1658525 | Y13: -0.0293175 | Z13: -0.01203 | AA13: 0.03607 | AB13: 0.4328275 | AC13: 0.38982 | AD13: 0.3984725 | AE13: 0.30725 | AF13: 0.6580775 | AG13: 0.6649675 | AH13: 0.6645875 | AI13: 0.8071325 | AJ13: 1.0589975 | AK13: 1.059485 | AL13: 1.0104525 | AM13: 1.2115575 | AN13: 1.1994475 | AO13: 1.20271 | AP13: 1.079205 | AQ13: 1.138115 | AR13: 1.21389 | AS13: 1.18919 | AT13: 1.2047925 | AU13: 1.3652525 | AV13: 1.3375925 | AW13: 1.336495 | AX13: 1.2893025 | AY13: 1.314775 | AZ13: 1.340785 | BA13: 1.38491 | BB13: 1.3893275 | BC13: 1.3825175 | BD13: 1.4356575 | BE13: 1.4751125 | BF13: 1.50591 | BG13: 1.4912825 | BH13: 1.6717175
A14: 2.6164076 | B14: =1.158*A14 -> 3.0298 | C14: =1/A14 -> 0.38220345 | E14: 0 | F14: 0.005801375 | G14: 0.13414407 | H14: 0.0223508 | I14: 0.00929675 | J14: 0.0085565 | K14: 0.076926 | L14: 0.05737025 | M14: -0.0041601 | N14: -0.00141095 | O14: 0.01223525 | P14: 0.1660175 | Q14: 0.035485 | R14: 0.0745575 | S14: 0.0563225 | T14: 0.1586975 | U14: 0.057 | V14: -0.0114825 | W14: 0.093755 | X14: 0.1651825 | Y14: -0.03245 | Z14: -0.01073 | AA14: 0.0289525 | AB14: 0.432545 | AC14: 0.3937625 | AD14: 0.393695 | AE14: 0.30133 | AF14: 0.653245 | AG14: 0.6650325 | AH14: 0.6610475 | AI14: 0.7975725 | AJ14: 1.055145 | AK14: 1.0562075 | AL14: 1.0081 | AM14: 1.25667 | AN14: 1.247085 | AO14: 1.24769 | AP14: 1.0730125 | AQ14: 1.1588275 | AR14: 1.2588825 | AS14: 1.229545 | AT14: 1.247185 | AU14: 1.43194 | AV14: 1.3984275 | AW14: 1.3951375 | AX14: 1.345045 | AY14: 1.36999 | AZ14: 1.40527 | BA14: 1.44703 | BB14: 1.4499625 | BC14: 1.4460675 | BD14: 1.501945 | BE14: 1.5594475 | BF14: 1.59326 | BG14: 1.6056025 | BH14: 1.779185
... A17: 2.3573402 | B17: =1.158*A17 -> 2.7298 | C17: =1/A17 -> 0.4242069 | E17: 0 | F17: -0.007862925 | G17: 0.13610707 | H17: 0.028407475 | I17: 0.04899575 | J17: 0.04250875 | K17: 0.10668075 | L17: 0.0843495 | M17: -0.00453135 | N17: -0.0084484 | O17: 0.01329925 | P17: 0.1877475 | Q17: 0.0165575 | R17: 0.099735 | S17: 0.050205 | T17: 0.1764325 | U17: 0.07934 | V17: -0.0257475 | W17: 0.0950725 | X17: 0.177545 | Y17: -0.0447675 | Z17: -0.0184075 | AA17: 0.002795 | AB17: 0.084675 | AC17: 0.0490175 | AD17: 0.00736 | AE17: -0.050135 | AF17: 0.1593125 | AG17: 0.1909025 | AH17: 0.170165 | AI17: 0.238485 | AJ17: 0.475785 | AK17: 0.4691375 | AL17: 0.4296725 | AM17: 0.618965 | AN17: 0.60742 | AO17: 0.6000225 | AP17: 0.4413 | AQ17: 0.5263275 | AR17: 0.663695 | AS17: 0.6038475 | AT17: 0.6295925 | AU17: 0.7635175 | AV17: 0.70991 | AW17: 0.7017475 | AX17: 0.6694225 | AY17: 0.672645 | AZ17: 0.7057325 | BA17: 0.724865 | BB17: 0.7202325 | BC17: 0.720275 | BD17: 0.7666075 | BE17: 0.818495 | BF17: 0.85304 | BG17: 0.89678 | BH17: 1.1060525
D24: =D1 -> P [kN] | E24: =MAX($E1:E1) -> 0 | F24: =MAX($E1:F1) -> 50 | G24: =MAX($E1:G1) -> 51 | H24: =MAX($E1:H1) -> 51 | I24: =MAX($E1:I1) -> 91 | J24: =MAX($E1:J1) -> 91 | K24: =MAX($E1:K1) -> 93 | L24: =MAX($E1:L1) -> 98 | ... BH24: =MAX($E1:BH1) -> 263
A25: =A2 -> M/(Vd) | B25: =B2 -> x | C25: =C2 -> Vd/M | D25: =D2 -> V [kN] | E25: =MAX($E2:E2) -> 30 | F25: =MAX($E2:F2) -> 55 | G25: =MAX($E2:G2) -> 55.5 | H25: =MAX($E2:H2) -> 55.5 | I25: =MAX($E2:I2) -> 75.5 | J25: =MAX($E2:J2) -> 75.5 | K25: =MAX($E2:K2) -> 76.5 | L25: =MAX($E2:L2) -> 79 | ... BH25: =MAX($E2:BH2) -> 161.5
A26: 3.5663212 | B26: =1.158*A26 -> 4.1298 | C26: =C3 -> 0.28040099 | E26: =MAX($E3:E3) -> 0 | F26: =MAX($E3:F3) -> 0.0227154 | G26: =MAX($E3:G3) -> 0.1603122 | H26: =MAX($E3:H3) -> 0.1603122 | I26: =MAX($E3:I3) -> 0.1603122 | J26: =MAX($E3:J3) -> 0.1603122 | K26: =MAX($E3:K3) -> 0.1603122 | L26: =MAX($E3:L3) -> 0.1603122 | ... BH26: =MAX($E3:BH3) -> 1.81375
A27: 3.4799655 | B27: =1.158*A27 -> 4.0298 | C27: =C4 -> 0.28735917 | E27: =MAX($E4:E4) -> 0 | F27: =MAX($E4:F4) -> 0.02485995 | G27: =MAX($E4:G4) -> 0.14192503 | H27: =MAX($E4:H4) -> 0.14192503 | I27: =MAX($E4:I4) -> 0.14192503 | J27: =MAX($E4:J4) -> 0.14192503 | K27: =MAX($E4:K4) -> 0.14192503 | L27: =MAX($E4:L4) -> 0.14192503 | ... BH27: =MAX($E4:BH4) -> 1.6304875
A28: 3.3936097 | B28: =1.158*A28 -> 3.9298 | C28: =C5 -> 0.29467148 | E28: =MAX($E5:E5) -> 0 | F28: =MAX($E5:F5) -> 0.025106075 | G28: =MAX($E5:G5) -> 0.13579648 | H28: =MAX($E5:H5) -> 0.13579648 | I28: =MAX($E5:I5) -> 0.13579648 | J28: =MAX($E5:J5) -> 0.13579648 | K28: =MAX($E5:K5) -> 0.13579648 | L28: =MAX($E5:L5) -> 0.13579648 | ... BH28: =MAX($E5:BH5) -> 1.5397725
A29: 3.3072539 | B29: =1.158*A29 -> 3.8298 | C29: =C6 -> 0.30236566 | E29: =MAX($E6:E6) -> 0 | F29: =MAX($E6:F6) -> 0.024103375 | G29: =MAX($E6:G6) -> 0.13046188 | H29: =MAX($E6:H6) -> 0.13046188 | I29: =MAX($E6:I6) -> 0.13046188 | J29: =MAX($E6:J6) -> 0.13046188 | K29: =MAX($E6:K6) -> 0.13046188 | L29: =MAX($E6:L6) -> 0.13046188 | ... BH29: =MAX($E6:BH6) -> 1.80868
A30: 3.2208981 | B30: =1.158*A30 -> 3.7298 | C30: =C7 -> 0.31047241 | E30: =MAX($E7:E7) -> 0 | F30: =MAX($E7:F7) -> 0.0255173 | G30: =MAX($E7:G7) -> 0.13230312 | H30: =MAX($E7:H7) -> 0.13230312 | I30: =MAX($E7:I7) -> 0.13230312 | J30: =MAX($E7:J7) -> 0.13230312 | K30: =MAX($E7:K7) -> 0.13230312 | L30: =MAX($E7:L7) -> 0.13230312 | ... BH30: =MAX($E7:BH7) -> 1.9170925
A31: 3.1345423 | B31: =1.158*A31 -> 3.6298 | C31: =C8 -> 0.31902584 | E31: =MAX($E8:E8) -> 0 | F31: =MAX($E8:F8) -> 0.0210364 | G31: =MAX($E8:G8) -> 0.13178857 | H31: =MAX($E8:H8) -> 0.13178857 | I31: =MAX($E8:I8) -> 0.13178857 | J31: =MAX($E8:J8) -> 0.13178857 | K31: =MAX($E8:K8) -> 0.13178857 | L31: =MAX($E8:L8) -> 0.13178857 | ... BH31: =MAX($E8:BH8) -> 1.6414025
A32: 3.0481865 | B32: =1.158*A32 -> 3.5298 | C32: =C9 -> 0.32806391 | E32: =MAX($E9:E9) -> 0 | F32: =MAX($E9:F9) -> 0.02476305 | G32: =MAX($E9:G9) -> 0.136351 | H32: =MAX($E9:H9) -> 0.136351 | I32: =MAX($E9:I9) -> 0.136351 | J32: =MAX($E9:J9) -> 0.136351 | K32: =MAX($E9:K9) -> 0.136351 | L32: =MAX($E9:L9) -> 0.136351 | ... BH32: =MAX($E9:BH9) -> 1.7157275
A33: 2.9618307 | B33: =1.158*A33 -> 3.4298 | C33: =C10 -> 0.33762902 | E33: =MAX($E10:E10) -> 0 | F33: =MAX($E10:F10) -> 0.023636575 | G33: =MAX($E10:G10) -> 0.13995727 | H33: =MAX($E10:H10) -> 0.13995727 | I33: =MAX($E10:I10) -> 0.13995727 | J33: =MAX($E10:J10) -> 0.13995727 | K33: =MAX($E10:K10) -> 0.13995727 | L33: =MAX($E10:L10) -> 0.13995727 | ... BH33: =MAX($E10:BH10) -> 1.6996233
A34: 2.875475 | B34: =1.158*A34 -> 3.3298 | C34: =C11 -> 0.34776863 | E34: =MAX($E11:E11) -> 0 | F34: =MAX($E11:F11) -> 0.021477125 | G34: =MAX($E11:G11) -> 0.1357674 | H34: =MAX($E11:H11) -> 0.1357674 | I34: =MAX($E11:I11) -> 0.1357674 | J34: =MAX($E11:J11) -> 0.1357674 | K34: =MAX($E11:K11) -> 0.1357674 | L34: =MAX($E11:L11) -> 0.1357674 | ... BH34: =MAX($E11:BH11) -> 1.8312933
A35: 2.7891192 | B35: =1.158*A35 -> 3.2298 | C35: =C12 -> 0.35853613 | E35: =MAX($E12:E12) -> 0 | F35: =MAX($E12:F12) -> 0.016847425 | G35: =MAX($E12:G12) -> 0.12990252 | H35: =MAX($E12:H12) -> 0.12990252 | I35: =MAX($E12:I12) -> 0.12990252 | J35: =MAX($E12:J12) -> 0.12990252 | K35: =MAX($E12:K12) -> 0.12990252 | L35: =MAX($E12:L12) -> 0.12990252 | ... BH35: =MAX($E12:BH12) -> 1.5789975
A36: 2.7027634 | B36: =1.158*A36 -> 3.1298 | C36: =C13 -> 0.36999169 | E36: =MAX($E13:E13) -> 0 | F36: =MAX($E13:F13) -> 0.011910075 | G36: =MAX($E13:G13) -> 0.13243835 | H36: =MAX($E13:H13) -> 0.13243835 | I36: =MAX($E13:I13) -> 0.13243835 | J36: =MAX($E13:J13) -> 0.13243835 | K36: =MAX($E13:K13) -> 0.13243835 | L36: =MAX($E13:L13) -> 0.13243835 | ... BH36: =MAX($E13:BH13) -> 1.6717175
A37: 2.6164076 | B37: =1.158*A37 -> 3.0298 | C37: =C14 -> 0.38220345 | E37: =MAX($E14:E14) -> 0 | F37: =MAX($E14:F14) -> 0.005801375 | G37: =MAX($E14:G14) -> 0.13414407 | H37: =MAX($E14:H14) -> 0.13414407 | I37: =MAX($E14:I14) -> 0.13414407 | J37: =MAX($E14:J14) -> 0.13414407 | K37: =MAX($E14:K14) -> 0.13414407 | L37: =MAX($E14:L14) -> 0.13414407 | ... BH37: =MAX($E14:BH14) -> 1.779185
... A40: 2.3573402 | B40: =1.158*A40 -> 2.7298 | C40: =C17 -> 0.4242069 | E40: =MAX($E17:E17) -> 0 | F40: =MAX($E17:F17) -> 0 | G40: =MAX($E17:G17) -> 0.13610707 | H40: =MAX($E17:H17) -> 0.13610707 | I40: =MAX($E17:I17) -> 0.13610707 | J40: =MAX($E17:J17) -> 0.13610707 | K40: =MAX($E17:K17) -> 0.13610707 | L40: =MAX($E17:L17) -> 0.13610707 | ... BH40: =MAX($E17:BH17) -> 1.1060525
D47: w_max | E47: =MAX(E26:E45) -> 0 | F47: =MAX(F26:F45) -> 0.0255173 | G47: =MAX(G26:G45) -> 0.1603122 | H47: =MAX(H26:H45) -> 0.1603122 | I47: =MAX(I26:I45) -> 0.1603122 | J47: =MAX(J26:J45) -> 0.1603122 | K47: =MAX(K26:K45) -> 0.1603122 | L47: =MAX(L26:L45) -> 0.1603122 | ... BH47: =MAX(BH26:BH45) -> 1.9170925 | BI47: 10
D48: w_max,w | E48: {=MAX($C26:$C45*E26:E45)} -> 0 | F48: {=MAX($C26:$C45*F26:F45)} -> 0.0081238631 | G48: {=MAX($C26:$C45*G26:G45)} -> 0.057737561 | H48: {=MAX($C26:$C45*H26:H45)} -> 0.057737561 | I48: {=MAX($C26:$C45*I26:I45)} -> 0.057737561 | J48: {=MAX($C26:$C45*J26:J45)} -> 0.057737561 | K48: {=MAX($C26:$C45*K26:K45)} -> 0.057737561 | L48: {=MAX($C26:$C45*L26:L45)} -> 0.057737561 | ... BH48: {=MAX($C26:$C45*BH26:BH45)} -> 0.68001064 | BI48: 10
D49: V_u/V | E49: =MAX($E25:$BH25)/E25 -> 5.3833333 | F49: =MAX($E25:$BH25)/F25 -> 2.9363636 | G49: =MAX($E25:$BH25)/G25 -> 2.9099099 | H49: =MAX($E25:$BH25)/H25 -> 2.9099099 | I49: =MAX($E25:$BH25)/I25 -> 2.1390728 | J49: =MAX($E25:$BH25)/J25 -> 2.1390728 | K49: =MAX($E25:$BH25)/K25 -> 2.1111111 | L49: =MAX($E25:$BH25)/L25 -> 2.0443038 | ... BH49: =MAX($E25:$BH25)/BH25 -> 1 | BI49: 1
D50: V/V_u | E50: =E25/MAX($E25:$BH25) -> 0.18575851 | F50: =F25/MAX($E25:$BH25) -> 0.34055728 | G50: =G25/MAX($E25:$BH25) -> 0.34365325 | H50: =H25/MAX($E25:$BH25) -> 0.34365325 | I50: =I25/MAX($E25:$BH25) -> 0.46749226 | J50: =J25/MAX($E25:$BH25) -> 0.46749226 | K50: =K25/MAX($E25:$BH25) -> 0.47368421 | L50: =L25/MAX($E25:$BH25) -> 0.48916409 | ... BH50: =BH25/MAX($E25:$BH25) -> 1

Sheet H403
D1: P [kN] | E1: 0 | F1: 126 | G1: 126 | H1: 134 | I1: 135 | J1: 135 | K1: 143 | L1: 144 | M1: 145 | N1: 151 | O1: 152 | P1: 154 | Q1: 166 | R1: 163 | S1: 166 | T1: 166 | U1: 165 | V1: 166 | W1: 164 | X1: 165 | Y1: 165 | Z1: 173 | AA1: 194 | AB1: 194 | AC1: 194 | AD1: 216 | AE1: 216 | AF1: 216 | AG1: 218 | AH1: 218 | AI1: 219 | AJ1: 245 | AK1: 246 | AL1: 246 | AM1: 269 | AN1: 269 | AO1: 269 | AP1: 292 | AQ1: 292 | AR1: 292 | AS1: 292 | AT1: 293 | AU1: 293 | AV1: 294 | AW1: 293 | AX1: 293 | AY1: 293 | AZ1: 294 | BA1: 308 | BB1: 308 | BC1: 309 | BD1: 313 | BE1: 321 | BF1: 321 | BG1: 321 | BH1: 326 | BI1: 327 | BJ1: 327 | BK1: 329 | BL1: 330 | BM1: 328 | BN1: 329 | BO1: 332 | BP1: 334 | BQ1: 334 | BR1: 335 | BS1: 335 | BT1: 336 | BU1: 336 | BV1: 337 | BW1: 337 | BX1: 338 | BY1: 338 | BZ1: 338 | CA1: 339 | CB1: 339 | CC1: 339 | CD1: 339 | CE1: 340 | CF1: 340 | CG1: 339 | CH1: 340 | CI1: 339 | CJ1: 339 | CK1: 339 | CL1: 337 | CM1: 337 | CN1: 344 | CO1: 346 | CP1: 346 | CQ1: 346
A2: M/(Vd) | B2: x | C2: Vd/M | D2: V [kN] | E2: =30+E1/2 -> 30 | F2: =30+F1/2 -> 93 | G2: =30+G1/2 -> 93 | H2: =30+H1/2 -> 97 | I2: =30+I1/2 -> 97.5 | J2: =30+J1/2 -> 97.5 | K2: =30+K1/2 -> 101.5 | L2: =30+L1/2 -> 102 | ... CQ2: =30+CQ1/2 -> 203
A3: 3.4480914 | B3: =1.158*A3 -> 3.9928898 | C3: =1/A3 -> 0.29001552 | E3: 0 | F3: 0.0969145 | G3: 0.091724 | H3: 0.7215895 | I3: 0.72212825 | J3: 0.637465 | K3: 0.56379 | L3: 0.83152175 | M3: 0.841419 | N3: 0.7034375 | O3: 0.90918 | P3: 0.9179675 | Q3: 1.0343075 | R3: 0.825445 | S3: 0.970815 | T3: 1.090365 | U3: 1.0936952 | V3: 1.0870115 | W3: 1.1353545 | X3: 1.1371785 | Y3: 1.068715 | Z3: 1.186241 | AA3: 1.1316225 | AB3: 1.12926 | AC3: 1.191445 | AD3: 1.26797 | AE3: 1.2698725 | AF3: 1.1521375 | AG3: 1.3136675 | AH3: 1.4161925 | AI3: 1.32556 | AJ3: 1.47789 | AK3: 1.5733425 | AL3: 1.56904 | AM3: 1.7892875 | AN3: 1.719485 | AO3: 1.8152725 | AP3: 1.88581 | AQ3: 1.88605 | AR3: 1.740415 | AS3: 1.72809 | AT3: 1.81479 | AU3: 1.811725 | AV3: 1.8175625 | AW3: 1.7831375 | AX3: 1.8739725 | AY3: 1.950245 | AZ3: 1.8334 | BA3: 2.059415 | BB3: 1.83224 | BC3: 1.9583225 | BD3: 1.98218 | BE3: 2.1547125 | BF3: 2.0438675 | BG3: 2.12262 | BH3: 2.104555 | BI3: 2.1045725 | BJ3: 2.0437925 | BK3: 2.2048625 | BL3: 2.052785 | BM3: 2.1558475 | BN3: 2.0905775 | BO3: 2.2850025 | BP3: 2.19535 | BQ3: 2.20409 | BR3: 2.31499 | BS3: 2.319505 | BT3: 2.2251075 | BU3: 2.4279275 | BV3: 2.20238 | BW3: 2.200125 | BX3: 2.293115 | BY3: 2.2353625 | BZ3: 2.4295225 | CA3: 2.42986 | CB3: 2.2600325 | CC3: 2.35634 | CD3: 2.3587025 | CE3: 2.2608025 | CF3: 2.3838225 | CG3: 2.3868225 | CH3: 2.3940775 | CI3: 2.3959325 | CJ3: 2.3873225 | CK3: 2.2807475 | CL3: 2.399735 | CM3: 2.2972275 | CN3: 2.36756 | CO3: 2.50236 | CP3: 2.567315 | CQ3: 2.56351
A4: 3.3617356 | B4: =1.158*A4 -> 3.8928898 | C4: =1/A4 -> 0.29746539 | E4: 0 | F4: 0.0890955 | G4: 0.085148 | H4: 0.555065 | I4: 0.553895 | J4: 0.4837725 | K4: 0.4266975 | L4: 0.6673275 | M4: 0.6747625 | N4: 0.57718 | O4: 0.7553 | P4: 0.7636075 | Q4: 0.95738 | R4: 0.7776175 | S4: 0.9018475 | T4: 1.0017575 | U4: 1.00389 | V4: 0.9978825 | W4: 1.043695 | X4: 1.0459175 | Y4: 0.9848475 | Z4: 1.087635 | AA4: 1.041655 | AB4: 1.0372125 | AC4: 1.091715 | AD4: 1.1657 | AE4: 1.168285 | AF4: 1.0673975 | AG4: 1.207535 | AH4: 1.3017775 | AI4: 1.2219575 | AJ4: 1.3609975 | AK4: 1.4396525 | AL4: 1.4351675 | AM4: 1.6396675 | AN4: 1.578515 | AO4: 1.6620375 | AP4: 1.7305825 | AQ4: 1.731865 | AR4: 1.6082775 | AS4: 1.595725 | AT4: 1.6689175 | AU4: 1.6684725 | AV4: 1.6737575 | AW4: 1.6468025 | AX4: 1.7270825 | AY4: 1.790445 | AZ4: 1.696405 | BA4: 1.8912 | BB4: 1.69457 | BC4: 1.8061225 | BD4: 1.8224875 | BE4: 1.9782025 | BF4: 1.88186 | BG4: 1.951365 | BH4: 1.9370375 | BI4: 1.938955 | BJ4: 1.883235 | BK4: 2.02559 | BL4: 1.89529 | BM4: 1.9847325 | BN4: 1.930915 | BO4: 2.0956425 | BP4: 2.019125 | BQ4: 2.029705 | BR4: 2.1245525 | BS4: 2.1290925 | BT4: 2.0477025 | BU4: 2.2206475 | BV4: 2.0249275 | BW4: 2.02451 | BX4: 2.10322 | BY4: 2.0552225 | BZ4: 2.2254075 | CA4: 2.2274875 | CB4: 2.0778125 | CC4: 2.16531 | CD4: 2.16759 | CE4: 2.0845025 | CF4: 2.1897 | CG4: 2.190945 | CH4: 2.19798 | CI4: 2.1978675 | CJ4: 2.1889025 | CK4: 2.09951 | CL4: 2.20479 | CM4: 2.1146725 | CN4: 2.1784825 | CO4: 2.297035 | CP4: 2.353135 | CQ4: 2.350045
A5: 3.2753798 | B5: =1.158*A5 -> 3.7928898 | C5: =1/A5 -> 0.3053081 | E5: 0 | F5: 0.08100925 | G5: 0.07703725 | H5: 0.46431 | I5: 0.465105 | J5: 0.4017325 | K5: 0.3651725 | L5: 0.5726 | M5: 0.5801225 | N5: 0.51016 | O5: 0.66763 | P5: 0.6761 | Q5: 0.8977525 | R5: 0.73671 | S5: 0.845475 | T5: 0.9401625 | U5: 0.941975 | V5: 0.938395 | W5: 0.9790625 | X5: 0.980105 | Y5: 0.9278775 | Z5: 1.020055 | AA5: 0.9846675 | AB5: 0.9787825 | AC5: 1.0310925 | AD5: 1.1055475 | AE5: 1.1052425 | AF5: 1.0141075 | AG5: 1.1486175 | AH5: 1.2291675 | AI5: 1.15734 | AJ5: 1.292785 | AK5: 1.36056 | AL5: 1.35971 | AM5: 1.5509225 | AN5: 1.501095 | AO5: 1.57242 | AP5: 1.6476225 | AQ5: 1.64533 | AR5: 1.5360425 | AS5: 1.52453 | AT5: 1.5932575 | AU5: 1.595485 | AV5: 1.597775 | AW5: 1.5797275 | AX5: 1.649905 | AY5: 1.706955 | AZ5: 1.6195425 | BA5: 1.80609 | BB5: 1.6281575 | BC5: 1.7288575 | BD5: 1.7493475 | BE5: 1.89138 | BF5: 1.81027 | BG5: 1.868045 | BH5: 1.86059 | BI5: 1.8602775 | BJ5: 1.813575 | BK5: 1.93769 | BL5: 1.8247875 | BM5: 1.909995 | BN5: 1.8595525 | BO5: 2.009785 | BP5: 1.9417125 | BQ5: 1.953405 | BR5: 2.039175 | BS5: 2.042435 | BT5: 1.97329 | BU5: 2.1256925 | BV5: 1.951865 | BW5: 1.95238 | BX5: 2.02417 | BY5: 1.983625 | BZ5: 2.132755 | CA5: 2.1331775 | CB5: 2.00074 | CC5: 2.0763925 | CD5: 2.08175 | CE5: 2.0069675 | CF5: 2.10371 | CG5: 2.101805 | CH5: 2.114295 | CI5: 2.1121325 | CJ5: 2.1050125 | CK5: 2.0259375 | CL5: 2.1178275 | CM5: 2.04334 | CN5: 2.10447 | CO5: 2.21026 | CP5: 2.265195 | CQ5: 2.262085
